Workbook

Sheet Data
A1: Employee No | B1: Name of the Employee | C1: Employee's Email Address | D1: Employee's Mobile Number | E1: Employee's Gender | F1: Employee's Date of Birth | G1: HealthCare Membership Type | H1: HealthCare Membership Name | I1: Employee's Nominee name | J1: Employee's Nominee Gender | K1: Employee's Nominee Date of Birth | L1: Employee's NOMINEE REALTIONSHIP WITH EMPLOYEE | M1: Employee's Child 1 Gender | N1: Employee's Child 1 Date of Birth | O1: Employee's Child 2 Name | P1: Employee's Child 2 Gender | Q1: Employee's Child 2 Date of Birth | R1: Employee's Father Name | S1: Employee's Father Date of Birth | U1: Employee's Mother Name | V1: Employee's Mother Date of Birth | X1: Employee Date of Joining the organization | Y1: Employee Designation | Z1: Is Employee or their Spouse Pregnant? | AA1: Have any of the family member has suffered Covid in past 30 days? | AB1: Does Employee or their Spouse Smoke? | AC1: Is Anyone in the family diabetic, high BP or Thyroid? If yes, Provide details with Relation | AD1: Does anyone have a Critical Illness like Cancer, Tumor, etc. | AE1: Does anyone had any surgery in last 1 year or is planning any surgery in next 1 year? If yes, please provide details. | AF1: Is any of the following condition applicable? Bone or Joint Related disorders, Kidney or Urinary tract-related disorders including stones, Stomach, Liver, Pancreas Intestine, Gall Ballader related disorders, Mental health disorders. If yes, please provide details
A2: TW1003 | B2: Muniganti Shiva Kumar Chary | C2: =VLOOKUP(A2,'[1]Active Sheet '!$A:$F,6,0) -> shivacharymunganti@gmail.com | D2: 9182060292 | E2: Male | F2: 36024 | G2: Team Member
A3: PN1002 | B3: Shaik Noor Bhasa Muzeef | C3: =VLOOKUP(A3,'[1]Active Sheet '!$A:$F,6,0) -> shaikmuzeef9999@gmail.com | D3: 9959456647 | E3: Male | F3: 35863 | G3: Team Member
A4: PN1003 | B4: Bavirisetty Datta Venkata Ramana | C4: =VLOOKUP(A4,'[1]Active Sheet '!$A:$F,6,0) -> bavirisettidvramana@gmail.com | D4: 9390919698 | E4: Male | F4: 35776 | G4: Team Member
A5: PN1004 | B5: Anagandula Prasana | C5: =VLOOKUP(A5,'[1]Active Sheet '!$A:$F,6,0) -> prasanna@propenu.com | D5: 8185094463 | E5: Female | F5: 36161 | G5: Team Member
A6: PN1005 | B6: Rishika Pokala | C6: =VLOOKUP(A6,'[1]Active Sheet '!$A:$F,6,0) -> rishika@propenu.com | D6: 7670818560 | E6: Female | F6: 36695 | G6: Team Member
A7: PN1006 | B7: Harsad Shaik | C7: =VLOOKUP(A7,'[1]Active Sheet '!$A:$F,6,0) -> shaikharshad2728@gmail.com | D7: 7993371356 | E7: Male | F7: 38226 | G7: Team Member
A8: PN1007 | B8: Kavuru Vanitha | C8: =VLOOKUP(A8,'[1]Active Sheet '!$A:$F,6,0) -> kavuruvanitha@gmail.com | D8: 7382369238 | E8: Female | F8: 35221 | G8: Team Member
A9: PN1008 | B9: D Hemangi | C9: =VLOOKUP(A9,'[1]Active Sheet '!$A:$F,6,0) -> darlahemangi071@gmail.com | D9: 8247805962 | E9: Female | F9: 37202 | G9: Team Member
A10: TW1004 | B10: Vishnu Murthy | C10: =VLOOKUP(A10,'[1]Active Sheet '!$A:$F,6,0) -> vishnumurthy0116@gmail.com | D10: 9573526844 | E10: Male | F10: 37438 | G10: Team Member
A11: TW1005 | B11: D Sohan | C11: =VLOOKUP(A11,'[1]Active Sheet '!$A:$F,6,0) -> decondasohan1996@gmail.com | D11: 8886860400 | E11: Male | F11: 35333 | G11: Team Member
A12: TW1006 | B12: Dasari Srinivas Rao | C12: srinunivas432@gmail.com | D12: 630125943 | E12: Male | F12: 35569 | G12: Team Member

Sheet Data_Check
A1: Employee No | B1: Name of the Employee | C1: Employee's Email Address | D1: Employee's Mobile Number | E1: Employee's Gender | F1: Employee's Date of Birth | G1: HealthCare Membership Type | H1: HealthCare Membership | I1: Employee's Spouse Name | J1: Employee's Spouse Gender | K1: Employee's Spouse Date of Birth | L1: Employee's Child 1 Name | M1: Employee's Child 1 Gender | N1: Employee's Child 1 Date of Birth | O1: Employee's Child 2 Name | P1: Employee's Child 2 Gender | Q1: Employee's Child 2 Date of Birth
A2: =IF(Data!#REF!="","",IF(COUNTIFS(Data!A$1:Data!#REF!,Data!#REF!)<=1,0,1)) -> #REF! | C2: =IF(Data!#REF!="","",(IF(ISNUMBER(MATCH("*@*.?*",Data!#REF!,0)),0,1)+IF(COUNTIFS(Data!C$1:Data!#REF!,Data!#REF!)>1,1,0))) -> #REF! | D2: =IF(Data!#REF!="","",IF(ISNUMBER(Data!#REF!),IF(AND(Data!#REF!>999999999,Data!#REF!<=9999999999),IF(COUNTIFS(Data!D$1:Data!#REF!,Data!#REF!)<=1,0,1),1),1)) -> #REF! | E2: =IF(Data!#REF!="","",IF(ISNUMBER(MATCH(Data!#REF!,Data_Val!$A$2:$A$3,0)),0,1)) -> #REF! | F2: =IF(Data!#REF!="","",IF(ISNUMBER(Data!#REF!),IF(AND(Data!#REF!>(TODAY()-(Data_Val!$H$3*365.25)),Data!#REF!<=(TODAY()-(Data_Val!$H$2*365.25))),0,1),1)) -> #REF! | G2: =IF(Data!#REF!="","",IF(AND(Data!#REF!="",Data!#REF!<>""),1,IF(ISNUMBER(MATCH(Data!#REF!,Data_Val!$C$2:$C$5,0)),0,1))) -> #REF! | H2: =IF(Data!#REF!="","",IF(AND(Data!#REF!<>"",Data!#REF!=""),1,IF(Data!#REF!="",1,IF(ISNUMBER(MATCH(Data!#REF!,Data_Val!$D$2:$D$35,0)),0,1)))) -> #REF! | I2: =IF(Data!#REF!="","",IF(Data!#REF!=Data_Val!$C$2,IF(Data!#REF!="",0,1),0)) -> #REF! | J2: =IF(Data!#REF!="","",IF(ISNUMBER(MATCH(Data!#REF!,Data_Val!$A$2:$A$3,0)),0,1)) -> #REF! | K2: =IF(Data!#REF!="","",IF(ISNUMBER(Data!#REF!),IF(AND(Data!#REF!>(TODAY()-(Data_Val!$K$3*365.25)),Data!#REF!<=(TODAY()-(Data_Val!$K$2*365.25))),0,1),1)) -> #REF! | L2: =IF(Data!#REF!="","",IF(Data!#REF!=Data_Val!$C$2,IF(Data!#REF!="",0,1),0)) -> #REF! | M2: =IF(Data!#REF!="","",IF(ISNUMBER(MATCH(Data!#REF!,Data_Val!$A$2:$A$3,0)),0,1)) -> #REF! | N2: =IF(Data!#REF!="","",IF(ISNUMBER(Data!#REF!),IF(AND(Data!#REF!>(TODAY()-(Data_Val!$L$3*365.25)),Data!#REF!<=(TODAY()-(Data_Val!$L$2*365.25))),0,1),1)) -> #REF! | O2: =IF(Data!#REF!="","",IF(Data!#REF!=Data_Val!$C$2,IF(Data!#REF!="",0,1),0)) -> #REF! | P2: =IF(Data!#REF!="","",IF(ISNUMBER(MATCH(Data!#REF!,Data_Val!$A$2:$A$3,0)),0,1)) -> #REF! | Q2: =IF(Data!#REF!="","",IF(ISNUMBER(Data!#REF!),IF(AND(Data!#REF!>(TODAY()-(Data_Val!$L$3*365.25)),Data!#REF!<=(TODAY()-(Data_Val!$L$2*365.25))),0,1),1)) -> #REF!
A3: =IF(Data!#REF!="","",IF(COUNTIFS(Data!A$1:Data!#REF!,Data!#REF!)<=1,0,1)) -> #REF! | C3: =IF(Data!#REF!="","",(IF(ISNUMBER(MATCH("*@*.?*",Data!#REF!,0)),0,1)+IF(COUNTIFS(Data!C$1:Data!#REF!,Data!#REF!)>1,1,0))) -> #REF! | D3: =IF(Data!#REF!="","",IF(ISNUMBER(Data!#REF!),IF(AND(Data!#REF!>999999999,Data!#REF!<=9999999999),IF(COUNTIFS(Data!D$1:Data!#REF!,Data!#REF!)<=1,0,1),1),1)) -> #REF! | E3: =IF(Data!#REF!="","",IF(ISNUMBER(MATCH(Data!#REF!,Data_Val!$A$2:$A$3,0)),0,1)) -> #REF! | F3: =IF(Data!#REF!="","",IF(ISNUMBER(Data!#REF!),IF(AND(Data!#REF!>(TODAY()-(Data_Val!$H$3*365.25)),Data!#REF!<=(TODAY()-(Data_Val!$H$2*365.25))),0,1),1)) -> #REF! | G3: =IF(Data!#REF!="","",IF(AND(Data!#REF!="",Data!#REF!<>""),1,IF(ISNUMBER(MATCH(Data!#REF!,Data_Val!$C$2:$C$5,0)),0,1))) -> #REF! | H3: =IF(Data!#REF!="","",IF(AND(Data!#REF!<>"",Data!#REF!=""),1,IF(Data!#REF!="",1,IF(ISNUMBER(MATCH(Data!#REF!,Data_Val!$D$2:$D$35,0)),0,1)))) -> #REF! | I3: =IF(Data!#REF!="","",IF(Data!#REF!=Data_Val!$C$2,IF(Data!#REF!="",0,1),0)) -> #REF! | J3: =IF(Data!#REF!="","",IF(ISNUMBER(MATCH(Data!#REF!,Data_Val!$A$2:$A$3,0)),0,1)) -> #REF! | K3: =IF(Data!#REF!="","",IF(ISNUMBER(Data!#REF!),IF(AND(Data!#REF!>(TODAY()-(Data_Val!$K$3*365.25)),Data!#REF!<=(TODAY()-(Data_Val!$K$2*365.25))),0,1),1)) -> #REF! | L3: =IF(Data!#REF!="","",IF(Data!#REF!=Data_Val!$C$2,IF(Data!#REF!="",0,1),0)) -> #REF! | M3: =IF(Data!#REF!="","",IF(ISNUMBER(MATCH(Data!#REF!,Data_Val!$A$2:$A$3,0)),0,1)) -> #REF! | N3: =IF(Data!#REF!="","",IF(ISNUMBER(Data!#REF!),IF(AND(Data!#REF!>(TODAY()-(Data_Val!$L$3*365.25)),Data!#REF!<=(TODAY()-(Data_Val!$L$2*365.25))),0,1),1)) -> #REF! | O3: =IF(Data!#REF!="","",IF(Data!#REF!=Data_Val!$C$2,IF(Data!#REF!="",0,1),0)) -> #REF! | P3: =IF(Data!#REF!="","",IF(ISNUMBER(MATCH(Data!#REF!,Data_Val!$A$2:$A$3,0)),0,1)) -> #REF! | Q3: =IF(Data!#REF!="","",IF(ISNUMBER(Data!#REF!),IF(AND(Data!#REF!>(TODAY()-(Data_Val!$L$3*365.25)),Data!#REF!<=(TODAY()-(Data_Val!$L$2*365.25))),0,1),1)) -> #REF!
A4: =IF(Data!#REF!="","",IF(COUNTIFS(Data!A$1:Data!#REF!,Data!#REF!)<=1,0,1)) -> #REF! | C4: =IF(Data!#REF!="","",(IF(ISNUMBER(MATCH("*@*.?*",Data!#REF!,0)),0,1)+IF(COUNTIFS(Data!C$1:Data!#REF!,Data!#REF!)>1,1,0))) -> #REF! | D4: =IF(Data!#REF!="","",IF(ISNUMBER(Data!#REF!),IF(AND(Data!#REF!>999999999,Data!#REF!<=9999999999),IF(COUNTIFS(Data!D$1:Data!#REF!,Data!#REF!)<=1,0,1),1),1)) -> #REF! | E4: =IF(Data!#REF!="","",IF(ISNUMBER(MATCH(Data!#REF!,Data_Val!$A$2:$A$3,0)),0,1)) -> #REF! | F4: =IF(Data!#REF!="","",IF(ISNUMBER(Data!#REF!),IF(AND(Data!#REF!>(TODAY()-(Data_Val!$H$3*365.25)),Data!#REF!<=(TODAY()-(Data_Val!$H$2*365.25))),0,1),1)) -> #REF! | G4: =IF(Data!#REF!="","",IF(AND(Data!#REF!="",Data!#REF!<>""),1,IF(ISNUMBER(MATCH(Data!#REF!,Data_Val!$C$2:$C$5,0)),0,1))) -> #REF! | H4: =IF(Data!#REF!="","",IF(AND(Data!#REF!<>"",Data!#REF!=""),1,IF(Data!#REF!="",1,IF(ISNUMBER(MATCH(Data!#REF!,Data_Val!$D$2:$D$35,0)),0,1)))) -> #REF! | I4: =IF(Data!#REF!="","",IF(Data!#REF!=Data_Val!$C$2,IF(Data!#REF!="",0,1),0)) -> #REF! | J4: =IF(Data!#REF!="","",IF(ISNUMBER(MATCH(Data!#REF!,Data_Val!$A$2:$A$3,0)),0,1)) -> #REF! | K4: =IF(Data!#REF!="","",IF(ISNUMBER(Data!#REF!),IF(AND(Data!#REF!>(TODAY()-(Data_Val!$K$3*365.25)),Data!#REF!<=(TODAY()-(Data_Val!$K$2*365.25))),0,1),1)) -> #REF! | L4: =IF(Data!#REF!="","",IF(Data!#REF!=Data_Val!$C$2,IF(Data!#REF!="",0,1),0)) -> #REF! | M4: =IF(Data!#REF!="","",IF(ISNUMBER(MATCH(Data!#REF!,Data_Val!$A$2:$A$3,0)),0,1)) -> #REF! | N4: =IF(Data!#REF!="","",IF(ISNUMBER(Data!#REF!),IF(AND(Data!#REF!>(TODAY()-(Data_Val!$L$3*365.25)),Data!#REF!<=(TODAY()-(Data_Val!$L$2*365.25))),0,1),1)) -> #REF! | O4: =IF(Data!#REF!="","",IF(Data!#REF!=Data_Val!$C$2,IF(Data!#REF!="",0,1),0)) -> #REF! | P4: =IF(Data!#REF!="","",IF(ISNUMBER(MATCH(Data!#REF!,Data_Val!$A$2:$A$3,0)),0,1)) -> #REF! | Q4: =IF(Data!#REF!="","",IF(ISNUMBER(Data!#REF!),IF(AND(Data!#REF!>(TODAY()-(Data_Val!$L$3*365.25)),Data!#REF!<=(TODAY()-(Data_Val!$L$2*365.25))),0,1),1)) -> #REF!
A5: =IF(Data!#REF!="","",IF(COUNTIFS(Data!A$1:Data!#REF!,Data!#REF!)<=1,0,1)) -> #REF! | C5: =IF(Data!#REF!="","",(IF(ISNUMBER(MATCH("*@*.?*",Data!#REF!,0)),0,1)+IF(COUNTIFS(Data!C$1:Data!#REF!,Data!#REF!)>1,1,0))) -> #REF! | D5: =IF(Data!#REF!="","",IF(ISNUMBER(Data!#REF!),IF(AND(Data!#REF!>999999999,Data!#REF!<=9999999999),IF(COUNTIFS(Data!D$1:Data!#REF!,Data!#REF!)<=1,0,1),1),1)) -> #REF! | E5: =IF(Data!#REF!="","",IF(ISNUMBER(MATCH(Data!#REF!,Data_Val!$A$2:$A$3,0)),0,1)) -> #REF! | F5: =IF(Data!#REF!="","",IF(ISNUMBER(Data!#REF!),IF(AND(Data!#REF!>(TODAY()-(Data_Val!$H$3*365.25)),Data!#REF!<=(TODAY()-(Data_Val!$H$2*365.25))),0,1),1)) -> #REF! | G5: =IF(Data!#REF!="","",IF(AND(Data!#REF!="",Data!#REF!<>""),1,IF(ISNUMBER(MATCH(Data!#REF!,Data_Val!$C$2:$C$5,0)),0,1))) -> #REF! | H5: =IF(Data!#REF!="","",IF(AND(Data!#REF!<>"",Data!#REF!=""),1,IF(Data!#REF!="",1,IF(ISNUMBER(MATCH(Data!#REF!,Data_Val!$D$2:$D$35,0)),0,1)))) -> #REF! | I5: =IF(Data!#REF!="","",IF(Data!#REF!=Data_Val!$C$2,IF(Data!#REF!="",0,1),0)) -> #REF! | J5: =IF(Data!#REF!="","",IF(ISNUMBER(MATCH(Data!#REF!,Data_Val!$A$2:$A$3,0)),0,1)) -> #REF! | K5: =IF(Data!#REF!="","",IF(ISNUMBER(Data!#REF!),IF(AND(Data!#REF!>(TODAY()-(Data_Val!$K$3*365.25)),Data!#REF!<=(TODAY()-(Data_Val!$K$2*365.25))),0,1),1)) -> #REF! | L5: =IF(Data!#REF!="","",IF(Data!#REF!=Data_Val!$C$2,IF(Data!#REF!="",0,1),0)) -> #REF! | M5: =IF(Data!#REF!="","",IF(ISNUMBER(MATCH(Data!#REF!,Data_Val!$A$2:$A$3,0)),0,1)) -> #REF! | N5: =IF(Data!#REF!="","",IF(ISNUMBER(Data!#REF!),IF(AND(Data!#REF!>(TODAY()-(Data_Val!$L$3*365.25)),Data!#REF!<=(TODAY()-(Data_Val!$L$2*365.25))),0,1),1)) -> #REF! | O5: =IF(Data!#REF!="","",IF(Data!#REF!=Data_Val!$C$2,IF(Data!#REF!="",0,1),0)) -> #REF! | P5: =IF(Data!#REF!="","",IF(ISNUMBER(MATCH(Data!#REF!,Data_Val!$A$2:$A$3,0)),0,1)) -> #REF! | Q5: =IF(Data!#REF!="","",IF(ISNUMBER(Data!#REF!),IF(AND(Data!#REF!>(TODAY()-(Data_Val!$L$3*365.25)),Data!#REF!<=(TODAY()-(Data_Val!$L$2*365.25))),0,1),1)) -> #REF!
A6: =IF(Data!#REF!="","",IF(COUNTIFS(Data!A$1:Data!#REF!,Data!#REF!)<=1,0,1)) -> #REF! | C6: =IF(Data!#REF!="","",(IF(ISNUMBER(MATCH("*@*.?*",Data!#REF!,0)),0,1)+IF(COUNTIFS(Data!C$1:Data!#REF!,Data!#REF!)>1,1,0))) -> #REF! | D6: =IF(Data!#REF!="","",IF(ISNUMBER(Data!#REF!),IF(AND(Data!#REF!>999999999,Data!#REF!<=9999999999),IF(COUNTIFS(Data!D$1:Data!#REF!,Data!#REF!)<=1,0,1),1),1)) -> #REF! | E6: =IF(Data!#REF!="","",IF(ISNUMBER(MATCH(Data!#REF!,Data_Val!$A$2:$A$3,0)),0,1)) -> #REF! | F6: =IF(Data!#REF!="","",IF(ISNUMBER(Data!#REF!),IF(AND(Data!#REF!>(TODAY()-(Data_Val!$H$3*365.25)),Data!#REF!<=(TODAY()-(Data_Val!$H$2*365.25))),0,1),1)) -> #REF! | G6: =IF(Data!#REF!="","",IF(AND(Data!#REF!="",Data!#REF!<>""),1,IF(ISNUMBER(MATCH(Data!#REF!,Data_Val!$C$2:$C$5,0)),0,1))) -> #REF! | H6: =IF(Data!#REF!="","",IF(AND(Data!#REF!<>"",Data!#REF!=""),1,IF(Data!#REF!="",1,IF(ISNUMBER(MATCH(Data!#REF!,Data_Val!$D$2:$D$35,0)),0,1)))) -> #REF! | I6: =IF(Data!#REF!="","",IF(Data!#REF!=Data_Val!$C$2,IF(Data!#REF!="",0,1),0)) -> #REF! | J6: =IF(Data!#REF!="","",IF(ISNUMBER(MATCH(Data!#REF!,Data_Val!$A$2:$A$3,0)),0,1)) -> #REF! | K6: =IF(Data!#REF!="","",IF(ISNUMBER(Data!#REF!),IF(AND(Data!#REF!>(TODAY()-(Data_Val!$K$3*365.25)),Data!#REF!<=(TODAY()-(Data_Val!$K$2*365.25))),0,1),1)) -> #REF! | L6: =IF(Data!#REF!="","",IF(Data!#REF!=Data_Val!$C$2,IF(Data!#REF!="",0,1),0)) -> #REF! | M6: =IF(Data!#REF!="","",IF(ISNUMBER(MATCH(Data!#REF!,Data_Val!$A$2:$A$3,0)),0,1)) -> #REF! | N6: =IF(Data!#REF!="","",IF(ISNUMBER(Data!#REF!),IF(AND(Data!#REF!>(TODAY()-(Data_Val!$L$3*365.25)),Data!#REF!<=(TODAY()-(Data_Val!$L$2*365.25))),0,1),1)) -> #REF! | O6: =IF(Data!#REF!="","",IF(Data!#REF!=Data_Val!$C$2,IF(Data!#REF!="",0,1),0)) -> #REF! | P6: =IF(Data!#REF!="","",IF(ISNUMBER(MATCH(Data!#REF!,Data_Val!$A$2:$A$3,0)),0,1)) -> #REF! | Q6: =IF(Data!#REF!="","",IF(ISNUMBER(Data!#REF!),IF(AND(Data!#REF!>(TODAY()-(Data_Val!$L$3*365.25)),Data!#REF!<=(TODAY()-(Data_Val!$L$2*365.25))),0,1),1)) -> #REF!
A7: =IF(Data!#REF!="","",IF(COUNTIFS(Data!A$1:Data!#REF!,Data!#REF!)<=1,0,1)) -> #REF! | C7: =IF(Data!#REF!="","",(IF(ISNUMBER(MATCH("*@*.?*",Data!#REF!,0)),0,1)+IF(COUNTIFS(Data!C$1:Data!#REF!,Data!#REF!)>1,1,0))) -> #REF! | D7: =IF(Data!#REF!="","",IF(ISNUMBER(Data!#REF!),IF(AND(Data!#REF!>999999999,Data!#REF!<=9999999999),IF(COUNTIFS(Data!D$1:Data!#REF!,Data!#REF!)<=1,0,1),1),1)) -> #REF! | E7: =IF(Data!#REF!="","",IF(ISNUMBER(MATCH(Data!#REF!,Data_Val!$A$2:$A$3,0)),0,1)) -> #REF! | F7: =IF(Data!#REF!="","",IF(ISNUMBER(Data!#REF!),IF(AND(Data!#REF!>(TODAY()-(Data_Val!$H$3*365.25)),Data!#REF!<=(TODAY()-(Data_Val!$H$2*365.25))),0,1),1)) -> #REF! | G7: =IF(Data!#REF!="","",IF(AND(Data!#REF!="",Data!#REF!<>""),1,IF(ISNUMBER(MATCH(Data!#REF!,Data_Val!$C$2:$C$5,0)),0,1))) -> #REF! | H7: =IF(Data!#REF!="","",IF(AND(Data!#REF!<>"",Data!#REF!=""),1,IF(Data!#REF!="",1,IF(ISNUMBER(MATCH(Data!#REF!,Data_Val!$D$2:$D$35,0)),0,1)))) -> #REF! | I7: =IF(Data!#REF!="","",IF(Data!#REF!=Data_Val!$C$2,IF(Data!#REF!="",0,1),0)) -> #REF! | J7: =IF(Data!#REF!="","",IF(ISNUMBER(MATCH(Data!#REF!,Data_Val!$A$2:$A$3,0)),0,1)) -> #REF! | K7: =IF(Data!#REF!="","",IF(ISNUMBER(Data!#REF!),IF(AND(Data!#REF!>(TODAY()-(Data_Val!$K$3*365.25)),Data!#REF!<=(TODAY()-(Data_Val!$K$2*365.25))),0,1),1)) -> #REF! | L7: =IF(Data!#REF!="","",IF(Data!#REF!=Data_Val!$C$2,IF(Data!#REF!="",0,1),0)) -> #REF! | M7: =IF(Data!#REF!="","",IF(ISNUMBER(MATCH(Data!#REF!,Data_Val!$A$2:$A$3,0)),0,1)) -> #REF! | N7: =IF(Data!#REF!="","",IF(ISNUMBER(Data!#REF!),IF(AND(Data!#REF!>(TODAY()-(Data_Val!$L$3*365.25)),Data!#REF!<=(TODAY()-(Data_Val!$L$2*365.25))),0,1),1)) -> #REF! | O7: =IF(Data!#REF!="","",IF(Data!#REF!=Data_Val!$C$2,IF(Data!#REF!="",0,1),0)) -> #REF! | P7: =IF(Data!#REF!="","",IF(ISNUMBER(MATCH(Data!#REF!,Data_Val!$A$2:$A$3,0)),0,1)) -> #REF! | Q7: =IF(Data!#REF!="","",IF(ISNUMBER(Data!#REF!),IF(AND(Data!#REF!>(TODAY()-(Data_Val!$L$3*365.25)),Data!#REF!<=(TODAY()-(Data_Val!$L$2*365.25))),0,1),1)) -> #REF!
A8: =IF(Data!#REF!="","",IF(COUNTIFS(Data!A$1:Data!#REF!,Data!#REF!)<=1,0,1)) -> #REF! | C8: =IF(Data!#REF!="","",(IF(ISNUMBER(MATCH("*@*.?*",Data!#REF!,0)),0,1)+IF(COUNTIFS(Data!C$1:Data!#REF!,Data!#REF!)>1,1,0))) -> #REF! | D8: =IF(Data!#REF!="","",IF(ISNUMBER(Data!#REF!),IF(AND(Data!#REF!>999999999,Data!#REF!<=9999999999),IF(COUNTIFS(Data!D$1:Data!#REF!,Data!#REF!)<=1,0,1),1),1)) -> #REF! | E8: =IF(Data!#REF!="","",IF(ISNUMBER(MATCH(Data!#REF!,Data_Val!$A$2:$A$3,0)),0,1)) -> #REF! | F8: =IF(Data!#REF!="","",IF(ISNUMBER(Data!#REF!),IF(AND(Data!#REF!>(TODAY()-(Data_Val!$H$3*365.25)),Data!#REF!<=(TODAY()-(Data_Val!$H$2*365.25))),0,1),1)) -> #REF! | G8: =IF(Data!#REF!="","",IF(AND(Data!#REF!="",Data!#REF!<>""),1,IF(ISNUMBER(MATCH(Data!#REF!,Data_Val!$C$2:$C$5,0)),0,1))) -> #REF! | H8: =IF(Data!#REF!="","",IF(AND(Data!#REF!<>"",Data!#REF!=""),1,IF(Data!#REF!="",1,IF(ISNUMBER(MATCH(Data!#REF!,Data_Val!$D$2:$D$35,0)),0,1)))) -> #REF! | I8: =IF(Data!#REF!="","",IF(Data!#REF!=Data_Val!$C$2,IF(Data!#REF!="",0,1),0)) -> #REF! | J8: =IF(Data!#REF!="","",IF(ISNUMBER(MATCH(Data!#REF!,Data_Val!$A$2:$A$3,0)),0,1)) -> #REF! | K8: =IF(Data!#REF!="","",IF(ISNUMBER(Data!#REF!),IF(AND(Data!#REF!>(TODAY()-(Data_Val!$K$3*365.25)),Data!#REF!<=(TODAY()-(Data_Val!$K$2*365.25))),0,1),1)) -> #REF! | L8: =IF(Data!#REF!="","",IF(Data!#REF!=Data_Val!$C$2,IF(Data!#REF!="",0,1),0)) -> #REF! | M8: =IF(Data!#REF!="","",IF(ISNUMBER(MATCH(Data!#REF!,Data_Val!$A$2:$A$3,0)),0,1)) -> #REF! | N8: =IF(Data!#REF!="","",IF(ISNUMBER(Data!#REF!),IF(AND(Data!#REF!>(TODAY()-(Data_Val!$L$3*365.25)),Data!#REF!<=(TODAY()-(Data_Val!$L$2*365.25))),0,1),1)) -> #REF! | O8: =IF(Data!#REF!="","",IF(Data!#REF!=Data_Val!$C$2,IF(Data!#REF!="",0,1),0)) -> #REF! | P8: =IF(Data!#REF!="","",IF(ISNUMBER(MATCH(Data!#REF!,Data_Val!$A$2:$A$3,0)),0,1)) -> #REF! | Q8: =IF(Data!#REF!="","",IF(ISNUMBER(Data!#REF!),IF(AND(Data!#REF!>(TODAY()-(Data_Val!$L$3*365.25)),Data!#REF!<=(TODAY()-(Data_Val!$L$2*365.25))),0,1),1)) -> #REF!
A9: =IF(Data!#REF!="","",IF(COUNTIFS(Data!A$1:Data!#REF!,Data!#REF!)<=1,0,1)) -> #REF! | C9: =IF(Data!#REF!="","",(IF(ISNUMBER(MATCH("*@*.?*",Data!#REF!,0)),0,1)+IF(COUNTIFS(Data!C$1:Data!#REF!,Data!#REF!)>1,1,0))) -> #REF! | D9: =IF(Data!#REF!="","",IF(ISNUMBER(Data!#REF!),IF(AND(Data!#REF!>999999999,Data!#REF!<=9999999999),IF(COUNTIFS(Data!D$1:Data!#REF!,Data!#REF!)<=1,0,1),1),1)) -> #REF! | E9: =IF(Data!#REF!="","",IF(ISNUMBER(MATCH(Data!#REF!,Data_Val!$A$2:$A$3,0)),0,1)) -> #REF! | F9: =IF(Data!#REF!="","",IF(ISNUMBER(Data!#REF!),IF(AND(Data!#REF!>(TODAY()-(Data_Val!$H$3*365.25)),Data!#REF!<=(TODAY()-(Data_Val!$H$2*365.25))),0,1),1)) -> #REF! | G9: =IF(Data!#REF!="","",IF(AND(Data!#REF!="",Data!#REF!<>""),1,IF(ISNUMBER(MATCH(Data!#REF!,Data_Val!$C$2:$C$5,0)),0,1))) -> #REF! | H9: =IF(Data!#REF!="","",IF(AND(Data!#REF!<>"",Data!#REF!=""),1,IF(Data!#REF!="",1,IF(ISNUMBER(MATCH(Data!#REF!,Data_Val!$D$2:$D$35,0)),0,1)))) -> #REF! | I9: =IF(Data!#REF!="","",IF(Data!#REF!=Data_Val!$C$2,IF(Data!#REF!="",0,1),0)) -> #REF! | J9: =IF(Data!#REF!="","",IF(ISNUMBER(MATCH(Data!#REF!,Data_Val!$A$2:$A$3,0)),0,1)) -> #REF! | K9: =IF(Data!#REF!="","",IF(ISNUMBER(Data!#REF!),IF(AND(Data!#REF!>(TODAY()-(Data_Val!$K$3*365.25)),Data!#REF!<=(TODAY()-(Data_Val!$K$2*365.25))),0,1),1)) -> #REF! | L9: =IF(Data!#REF!="","",IF(Data!#REF!=Data_Val!$C$2,IF(Data!#REF!="",0,1),0)) -> #REF! | M9: =IF(Data!#REF!="","",IF(ISNUMBER(MATCH(Data!#REF!,Data_Val!$A$2:$A$3,0)),0,1)) -> #REF! | N9: =IF(Data!#REF!="","",IF(ISNUMBER(Data!#REF!),IF(AND(Data!#REF!>(TODAY()-(Data_Val!$L$3*365.25)),Data!#REF!<=(TODAY()-(Data_Val!$L$2*365.25))),0,1),1)) -> #REF! | O9: =IF(Data!#REF!="","",IF(Data!#REF!=Data_Val!$C$2,IF(Data!#REF!="",0,1),0)) -> #REF! | P9: =IF(Data!#REF!="","",IF(ISNUMBER(MATCH(Data!#REF!,Data_Val!$A$2:$A$3,0)),0,1)) -> #REF! | Q9: =IF(Data!#REF!="","",IF(ISNUMBER(Data!#REF!),IF(AND(Data!#REF!>(TODAY()-(Data_Val!$L$3*365.25)),Data!#REF!<=(TODAY()-(Data_Val!$L$2*365.25))),0,1),1)) -> #REF!
A10: =IF(Data!#REF!="","",IF(COUNTIFS(Data!A$1:Data!#REF!,Data!#REF!)<=1,0,1)) -> #REF! | C10: =IF(Data!#REF!="","",(IF(ISNUMBER(MATCH("*@*.?*",Data!#REF!,0)),0,1)+IF(COUNTIFS(Data!C$1:Data!#REF!,Data!#REF!)>1,1,0))) -> #REF! | D10: =IF(Data!#REF!="","",IF(ISNUMBER(Data!#REF!),IF(AND(Data!#REF!>999999999,Data!#REF!<=9999999999),IF(COUNTIFS(Data!D$1:Data!#REF!,Data!#REF!)<=1,0,1),1),1)) -> #REF! | E10: =IF(Data!#REF!="","",IF(ISNUMBER(MATCH(Data!#REF!,Data_Val!$A$2:$A$3,0)),0,1)) -> #REF! | F10: =IF(Data!#REF!="","",IF(ISNUMBER(Data!#REF!),IF(AND(Data!#REF!>(TODAY()-(Data_Val!$H$3*365.25)),Data!#REF!<=(TODAY()-(Data_Val!$H$2*365.25))),0,1),1)) -> #REF! | G10: =IF(Data!#REF!="","",IF(AND(Data!#REF!="",Data!#REF!<>""),1,IF(ISNUMBER(MATCH(Data!#REF!,Data_Val!$C$2:$C$5,0)),0,1))) -> #REF! | H10: =IF(Data!#REF!="","",IF(AND(Data!#REF!<>"",Data!#REF!=""),1,IF(Data!#REF!="",1,IF(ISNUMBER(MATCH(Data!#REF!,Data_Val!$D$2:$D$35,0)),0,1)))) -> #REF! | I10: =IF(Data!#REF!="","",IF(Data!#REF!=Data_Val!$C$2,IF(Data!#REF!="",0,1),0)) -> #REF! | J10: =IF(Data!#REF!="","",IF(ISNUMBER(MATCH(Data!#REF!,Data_Val!$A$2:$A$3,0)),0,1)) -> #REF! | K10: =IF(Data!#REF!="","",IF(ISNUMBER(Data!#REF!),IF(AND(Data!#REF!>(TODAY()-(Data_Val!$K$3*365.25)),Data!#REF!<=(TODAY()-(Data_Val!$K$2*365.25))),0,1),1)) -> #REF! | L10: =IF(Data!#REF!="","",IF(Data!#REF!=Data_Val!$C$2,IF(Data!#REF!="",0,1),0)) -> #REF! | M10: =IF(Data!#REF!="","",IF(ISNUMBER(MATCH(Data!#REF!,Data_Val!$A$2:$A$3,0)),0,1)) -> #REF! | N10: =IF(Data!#REF!="","",IF(ISNUMBER(Data!#REF!),IF(AND(Data!#REF!>(TODAY()-(Data_Val!$L$3*365.25)),Data!#REF!<=(TODAY()-(Data_Val!$L$2*365.25))),0,1),1)) -> #REF! | O10: =IF(Data!#REF!="","",IF(Data!#REF!=Data_Val!$C$2,IF(Data!#REF!="",0,1),0)) -> #REF! | P10: =IF(Data!#REF!="","",IF(ISNUMBER(MATCH(Data!#REF!,Data_Val!$A$2:$A$3,0)),0,1)) -> #REF! | Q10: =IF(Data!#REF!="","",IF(ISNUMBER(Data!#REF!),IF(AND(Data!#REF!>(TODAY()-(Data_Val!$L$3*365.25)),Data!#REF!<=(TODAY()-(Data_Val!$L$2*365.25))),0,1),1)) -> #REF!
A11: =IF(Data!#REF!="","",IF(COUNTIFS(Data!A$1:Data!#REF!,Data!#REF!)<=1,0,1)) -> #REF! | C11: =IF(Data!#REF!="","",(IF(ISNUMBER(MATCH("*@*.?*",Data!#REF!,0)),0,1)+IF(COUNTIFS(Data!C$1:Data!#REF!,Data!#REF!)>1,1,0))) -> #REF! | D11: =IF(Data!#REF!="","",IF(ISNUMBER(Data!#REF!),IF(AND(Data!#REF!>999999999,Data!#REF!<=9999999999),IF(COUNTIFS(Data!D$1:Data!#REF!,Data!#REF!)<=1,0,1),1),1)) -> #REF! | E11: =IF(Data!#REF!="","",IF(ISNUMBER(MATCH(Data!#REF!,Data_Val!$A$2:$A$3,0)),0,1)) -> #REF! | F11: =IF(Data!#REF!="","",IF(ISNUMBER(Data!#REF!),IF(AND(Data!#REF!>(TODAY()-(Data_Val!$H$3*365.25)),Data!#REF!<=(TODAY()-(Data_Val!$H$2*365.25))),0,1),1)) -> #REF! | G11: =IF(Data!#REF!="","",IF(AND(Data!#REF!="",Data!#REF!<>""),1,IF(ISNUMBER(MATCH(Data!#REF!,Data_Val!$C$2:$C$5,0)),0,1))) -> #REF! | H11: =IF(Data!#REF!="","",IF(AND(Data!#REF!<>"",Data!#REF!=""),1,IF(Data!#REF!="",1,IF(ISNUMBER(MATCH(Data!#REF!,Data_Val!$D$2:$D$35,0)),0,1)))) -> #REF! | I11: =IF(Data!#REF!="","",IF(Data!#REF!=Data_Val!$C$2,IF(Data!#REF!="",0,1),0)) -> #REF! | J11: =IF(Data!#REF!="","",IF(ISNUMBER(MATCH(Data!#REF!,Data_Val!$A$2:$A$3,0)),0,1)) -> #REF! | K11: =IF(Data!#REF!="","",IF(ISNUMBER(Data!#REF!),IF(AND(Data!#REF!>(TODAY()-(Data_Val!$K$3*365.25)),Data!#REF!<=(TODAY()-(Data_Val!$K$2*365.25))),0,1),1)) -> #REF! | L11: =IF(Data!#REF!="","",IF(Data!#REF!=Data_Val!$C$2,IF(Data!#REF!="",0,1),0)) -> #REF! | M11: =IF(Data!#REF!="","",IF(ISNUMBER(MATCH(Data!#REF!,Data_Val!$A$2:$A$3,0)),0,1)) -> #REF! | N11: =IF(Data!#REF!="","",IF(ISNUMBER(Data!#REF!),IF(AND(Data!#REF!>(TODAY()-(Data_Val!$L$3*365.25)),Data!#REF!<=(TODAY()-(Data_Val!$L$2*365.25))),0,1),1)) -> #REF! | O11: =IF(Data!#REF!="","",IF(Data!#REF!=Data_Val!$C$2,IF(Data!#REF!="",0,1),0)) -> #REF! | P11: =IF(Data!#REF!="","",IF(ISNUMBER(MATCH(Data!#REF!,Data_Val!$A$2:$A$3,0)),0,1)) -> #REF! | Q11: =IF(Data!#REF!="","",IF(ISNUMBER(Data!#REF!),IF(AND(Data!#REF!>(TODAY()-(Data_Val!$L$3*365.25)),Data!#REF!<=(TODAY()-(Data_Val!$L$2*365.25))),0,1),1)) -> #REF!
A12: =IF(Data!#REF!="","",IF(COUNTIFS(Data!A$1:Data!#REF!,Data!#REF!)<=1,0,1)) -> #REF! | C12: =IF(Data!#REF!="","",(IF(ISNUMBER(MATCH("*@*.?*",Data!#REF!,0)),0,1)+IF(COUNTIFS(Data!C$1:Data!#REF!,Data!#REF!)>1,1,0))) -> #REF! | D12: =IF(Data!#REF!="","",IF(ISNUMBER(Data!#REF!),IF(AND(Data!#REF!>999999999,Data!#REF!<=9999999999),IF(COUNTIFS(Data!D$1:Data!#REF!,Data!#REF!)<=1,0,1),1),1)) -> #REF! | E12: =IF(Data!#REF!="","",IF(ISNUMBER(MATCH(Data!#REF!,Data_Val!$A$2:$A$3,0)),0,1)) -> #REF! | F12: =IF(Data!#REF!="","",IF(ISNUMBER(Data!#REF!),IF(AND(Data!#REF!>(TODAY()-(Data_Val!$H$3*365.25)),Data!#REF!<=(TODAY()-(Data_Val!$H$2*365.25))),0,1),1)) -> #REF! | G12: =IF(Data!#REF!="","",IF(AND(Data!#REF!="",Data!#REF!<>""),1,IF(ISNUMBER(MATCH(Data!#REF!,Data_Val!$C$2:$C$5,0)),0,1))) -> #REF! | H12: =IF(Data!#REF!="","",IF(AND(Data!#REF!<>"",Data!#REF!=""),1,IF(Data!#REF!="",1,IF(ISNUMBER(MATCH(Data!#REF!,Data_Val!$D$2:$D$35,0)),0,1)))) -> #REF! | I12: =IF(Data!#REF!="","",IF(Data!#REF!=Data_Val!$C$2,IF(Data!#REF!="",0,1),0)) -> #REF! | J12: =IF(Data!#REF!="","",IF(ISNUMBER(MATCH(Data!#REF!,Data_Val!$A$2:$A$3,0)),0,1)) -> #REF! | K12: =IF(Data!#REF!="","",IF(ISNUMBER(Data!#REF!),IF(AND(Data!#REF!>(TODAY()-(Data_Val!$K$3*365.25)),Data!#REF!<=(TODAY()-(Data_Val!$K$2*365.25))),0,1),1)) -> #REF! | L12: =IF(Data!#REF!="","",IF(Data!#REF!=Data_Val!$C$2,IF(Data!#REF!="",0,1),0)) -> #REF! | M12: =IF(Data!#REF!="","",IF(ISNUMBER(MATCH(Data!#REF!,Data_Val!$A$2:$A$3,0)),0,1)) -> #REF! | N12: =IF(Data!#REF!="","",IF(ISNUMBER(Data!#REF!),IF(AND(Data!#REF!>(TODAY()-(Data_Val!$L$3*365.25)),Data!#REF!<=(TODAY()-(Data_Val!$L$2*365.25))),0,1),1)) -> #REF! | O12: =IF(Data!#REF!="","",IF(Data!#REF!=Data_Val!$C$2,IF(Data!#REF!="",0,1),0)) -> #REF! | P12: =IF(Data!#REF!="","",IF(ISNUMBER(MATCH(Data!#REF!,Data_Val!$A$2:$A$3,0)),0,1)) -> #REF! | Q12: =IF(Data!#REF!="","",IF(ISNUMBER(Data!#REF!),IF(AND(Data!#REF!>(TODAY()-(Data_Val!$L$3*365.25)),Data!#REF!<=(TODAY()-(Data_Val!$L$2*365.25))),0,1),1)) -> #REF!
A13: =IF(Data!B5="","",IF(COUNTIFS(Data!A$1:'Data'!A7,Data!A7)<=1,0,1)) -> 0 | C13: =IF(Data!C2="","",(IF(ISNUMBER(MATCH("*@*.?*",Data!C2,0)),0,1)+IF(COUNTIFS(Data!C$1:'Data'!C2,Data!C2)>1,1,0))) -> 0 | D13: =IF(Data!B5="","",IF(ISNUMBER(Data!D2),IF(AND(Data!D2>999999999,Data!D2<=9999999999),IF(COUNTIFS(Data!D$1:'Data'!D2,Data!D2)<=1,0,1),1),1)) -> 0 | E13: =IF(Data!B5="","",IF(ISNUMBER(MATCH(#REF!,Data_Val!$A$2:$A$3,0)),0,1)) -> 1 | F13: =IF(Data!B5="","",IF(ISNUMBER(#REF!),IF(AND(#REF!>(TODAY()-(Data_Val!$H$3*365.25)),#REF!<=(TODAY()-(Data_Val!$H$2*365.25))),0,1),1)) -> 1 | G13: =IF(Data!B5="","",IF(AND(#REF!="",#REF!<>""),1,IF(ISNUMBER(MATCH(#REF!,Data_Val!$C$2:$C$5,0)),0,1))) -> #REF! | H13: =IF(Data!B5="","",IF(AND(#REF!<>"",#REF!=""),1,IF(#REF!="",1,IF(ISNUMBER(MATCH(#REF!,Data_Val!$D$2:$D$35,0)),0,1)))) -> #REF! | I13: =IF(#REF!="","",IF(#REF!=Data_Val!$C$2,IF(#REF!="",0,1),0)) -> #REF! | J13: =IF(#REF!="","",IF(ISNUMBER(MATCH(#REF!,Data_Val!$A$2:$A$3,0)),0,1)) -> #REF! | K13: =IF(#REF!="","",IF(ISNUMBER(#REF!),IF(AND(#REF!>(TODAY()-(Data_Val!$K$3*365.25)),#REF!<=(TODAY()-(Data_Val!$K$2*365.25))),0,1),1)) -> #REF! | L13: =IF(#REF!="","",IF(#REF!=Data_Val!$C$2,IF(#REF!="",0,1),0)) -> #REF! | M13: =IF(#REF!="","",IF(ISNUMBER(MATCH(#REF!,Data_Val!$A$2:$A$3,0)),0,1)) -> #REF! | N13: =IF(#REF!="","",IF(ISNUMBER(#REF!),IF(AND(#REF!>(TODAY()-(Data_Val!$L$3*365.25)),#REF!<=(TODAY()-(Data_Val!$L$2*365.25))),0,1),1)) -> #REF! | O13: =IF(#REF!="","",IF(#REF!=Data_Val!$C$2,IF(#REF!="",0,1),0)) -> #REF! | P13: =IF(#REF!="","",IF(ISNUMBER(MATCH(#REF!,Data_Val!$A$2:$A$3,0)),0,1)) -> #REF! | Q13: =IF(#REF!="","",IF(ISNUMBER(#REF!),IF(AND(#REF!>(TODAY()-(Data_Val!$L$3*365.25)),#REF!<=(TODAY()-(Data_Val!$L$2*365.25))),0,1),1)) -> #REF!
A14: =IF(Data!B7="","",IF(COUNTIFS(Data!A$1:Data!#REF!,Data!#REF!)<=1,0,1)) -> #REF! | C14: =IF(#REF!="","",(IF(ISNUMBER(MATCH("*@*.?*",#REF!,0)),0,1)+IF(COUNTIFS(Data!C$1:#REF!,#REF!)>1,1,0))) -> #REF! | D14: =IF(Data!B7="","",IF(ISNUMBER(#REF!),IF(AND(#REF!>999999999,#REF!<=9999999999),IF(COUNTIFS(Data!D$1:#REF!,#REF!)<=1,0,1),1),1)) -> 1 | E14: =IF(Data!B7="","",IF(ISNUMBER(MATCH(Data!E2,Data_Val!$A$2:$A$3,0)),0,1)) -> 0 | F14: =IF(Data!B7="","",IF(ISNUMBER(Data!#REF!),IF(AND(Data!#REF!>(TODAY()-(Data_Val!$H$3*365.25)),Data!#REF!<=(TODAY()-(Data_Val!$H$2*365.25))),0,1),1)) -> 1 | G14: =IF(Data!B7="","",IF(AND(Data!G2="",Data!H2<>""),1,IF(ISNUMBER(MATCH(Data!G2,Data_Val!$C$2:$C$5,0)),0,1))) -> 0 | H14: =IF(Data!B7="","",IF(AND(Data!G2<>"",Data!H2=""),1,IF(Data!G2="",1,IF(ISNUMBER(MATCH(Data!H2,Data_Val!$D$2:$D$35,0)),0,1)))) -> 1 | I14: =IF(Data!G2="","",IF(Data!G2=Data_Val!$C$2,IF(Data!I2="",0,1),0)) -> 0 | J14: =IF(Data!I2="","",IF(ISNUMBER(MATCH(Data!J2,Data_Val!$A$2:$A$3,0)),0,1)) | K14: =IF(Data!I2="","",IF(ISNUMBER(Data!K2),IF(AND(Data!K2>(TODAY()-(Data_Val!$K$3*365.25)),Data!K2<=(TODAY()-(Data_Val!$K$2*365.25))),0,1),1)) | L14: =IF(Data!G2="","",IF(Data!G2=Data_Val!$C$2,IF(Data!L2="",0,1),0)) -> 0 | M14: =IF(Data!L2="","",IF(ISNUMBER(MATCH(Data!M2,Data_Val!$A$2:$A$3,0)),0,1)) | N14: =IF(Data!L2="","",IF(ISNUMBER(Data!N2),IF(AND(Data!N2>(TODAY()-(Data_Val!$L$3*365.25)),Data!N2<=(TODAY()-(Data_Val!$L$2*365.25))),0,1),1)) | O14: =IF(Data!$G2="","",IF(Data!$G2=Data_Val!$C$2,IF(Data!O2="",0,1),0)) -> 0 | P14: =IF(Data!O2="","",IF(ISNUMBER(MATCH(Data!P2,Data_Val!$A$2:$A$3,0)),0,1)) | Q14: =IF(Data!O2="","",IF(ISNUMBER(Data!Q2),IF(AND(Data!Q2>(TODAY()-(Data_Val!$L$3*365.25)),Data!Q2<=(TODAY()-(Data_Val!$L$2*365.25))),0,1),1))
A15: =IF(Data!#REF!="","",IF(COUNTIFS(Data!A$1:'Data'!A8,Data!A8)<=1,0,1)) -> #REF! | C15: =IF(Data!#REF!="","",(IF(ISNUMBER(MATCH("*@*.?*",Data!#REF!,0)),0,1)+IF(COUNTIFS(Data!C$1:Data!#REF!,Data!#REF!)>1,1,0))) -> #REF! | D15: =IF(Data!#REF!="","",IF(ISNUMBER(Data!#REF!),IF(AND(Data!#REF!>999999999,Data!#REF!<=9999999999),IF(COUNTIFS(Data!D$1:Data!#REF!,Data!#REF!)<=1,0,1),1),1)) -> #REF! | E15: =IF(Data!#REF!="","",IF(ISNUMBER(MATCH(Data!#REF!,Data_Val!$A$2:$A$3,0)),0,1)) -> #REF! | F15: =IF(Data!#REF!="","",IF(ISNUMBER(Data!#REF!),IF(AND(Data!#REF!>(TODAY()-(Data_Val!$H$3*365.25)),Data!#REF!<=(TODAY()-(Data_Val!$H$2*365.25))),0,1),1)) -> #REF! | G15: =IF(Data!#REF!="","",IF(AND(Data!#REF!="",Data!#REF!<>""),1,IF(ISNUMBER(MATCH(Data!#REF!,Data_Val!$C$2:$C$5,0)),0,1))) -> #REF! | H15: =IF(Data!#REF!="","",IF(AND(Data!#REF!<>"",Data!#REF!=""),1,IF(Data!#REF!="",1,IF(ISNUMBER(MATCH(Data!#REF!,Data_Val!$D$2:$D$35,0)),0,1)))) -> #REF! | I15: =IF(Data!#REF!="","",IF(Data!#REF!=Data_Val!$C$2,IF(Data!#REF!="",0,1),0)) -> #REF! | J15: =IF(Data!#REF!="","",IF(ISNUMBER(MATCH(Data!#REF!,Data_Val!$A$2:$A$3,0)),0,1)) -> #REF! | K15: =IF(Data!#REF!="","",IF(ISNUMBER(Data!#REF!),IF(AND(Data!#REF!>(TODAY()-(Data_Val!$K$3*365.25)),Data!#REF!<=(TODAY()-(Data_Val!$K$2*365.25))),0,1),1)) -> #REF! | L15: =IF(Data!#REF!="","",IF(Data!#REF!=Data_Val!$C$2,IF(Data!#REF!="",0,1),0)) -> #REF! | M15: =IF(Data!#REF!="","",IF(ISNUMBER(MATCH(Data!#REF!,Data_Val!$A$2:$A$3,0)),0,1)) -> #REF! | N15: =IF(Data!#REF!="","",IF(ISNUMBER(Data!#REF!),IF(AND(Data!#REF!>(TODAY()-(Data_Val!$L$3*365.25)),Data!#REF!<=(TODAY()-(Data_Val!$L$2*365.25))),0,1),1)) -> #REF! | O15: =IF(Data!#REF!="","",IF(Data!#REF!=Data_Val!$C$2,IF(Data!#REF!="",0,1),0)) -> #REF! | P15: =IF(Data!#REF!="","",IF(ISNUMBER(MATCH(Data!#REF!,Data_Val!$A$2:$A$3,0)),0,1)) -> #REF! | Q15: =IF(Data!#REF!="","",IF(ISNUMBER(Data!#REF!),IF(AND(Data!#REF!>(TODAY()-(Data_Val!$L$3*365.25)),Data!#REF!<=(TODAY()-(Data_Val!$L$2*365.25))),0,1),1)) -> #REF!
A16: =IF(Data!#REF!="","",IF(COUNTIFS(Data!A$1:'Data'!A11,Data!A11)<=1,0,1)) -> #REF! | C16: =IF(Data!F3="","",(IF(ISNUMBER(MATCH("*@*.?*",Data!F3,0)),0,1)+IF(COUNTIFS(Data!C$1:'Data'!F3,Data!F3)>1,1,0))) -> 1 | D16: =IF(Data!#REF!="","",IF(ISNUMBER(Data!#REF!),IF(AND(Data!#REF!>999999999,Data!#REF!<=9999999999),IF(COUNTIFS(Data!D$1:Data!#REF!,Data!#REF!)<=1,0,1),1),1)) -> #REF! | E16: =IF(Data!#REF!="","",IF(ISNUMBER(MATCH(Data!E5,Data_Val!$A$2:$A$3,0)),0,1)) -> #REF! | F16: =IF(Data!#REF!="","",IF(ISNUMBER(Data!#REF!),IF(AND(Data!#REF!>(TODAY()-(Data_Val!$H$3*365.25)),Data!#REF!<=(TODAY()-(Data_Val!$H$2*365.25))),0,1),1)) -> #REF! | G16: =IF(Data!#REF!="","",IF(AND(Data!G5="",Data!H5<>""),1,IF(ISNUMBER(MATCH(Data!G5,Data_Val!$C$2:$C$5,0)),0,1))) -> #REF! | H16: =IF(Data!#REF!="","",IF(AND(Data!G5<>"",Data!H5=""),1,IF(Data!G5="",1,IF(ISNUMBER(MATCH(Data!H5,Data_Val!$D$2:$D$35,0)),0,1)))) -> #REF! | I16: =IF(Data!G5="","",IF(Data!G5=Data_Val!$C$2,IF(Data!I5="",0,1),0)) -> 0 | J16: =IF(Data!I5="","",IF(ISNUMBER(MATCH(Data!J5,Data_Val!$A$2:$A$3,0)),0,1)) | K16: =IF(Data!I5="","",IF(ISNUMBER(Data!K5),IF(AND(Data!K5>(TODAY()-(Data_Val!$K$3*365.25)),Data!K5<=(TODAY()-(Data_Val!$K$2*365.25))),0,1),1)) | L16: =IF(Data!G5="","",IF(Data!G5=Data_Val!$C$2,IF(Data!L5="",0,1),0)) -> 0 | M16: =IF(Data!L5="","",IF(ISNUMBER(MATCH(Data!M5,Data_Val!$A$2:$A$3,0)),0,1)) | N16: =IF(Data!L5="","",IF(ISNUMBER(Data!N5),IF(AND(Data!N5>(TODAY()-(Data_Val!$L$3*365.25)),Data!N5<=(TODAY()-(Data_Val!$L$2*365.25))),0,1),1)) | O16: =IF(Data!$G5="","",IF(Data!$G5=Data_Val!$C$2,IF(Data!O5="",0,1),0)) -> 0 | P16: =IF(Data!O5="","",IF(ISNUMBER(MATCH(Data!P5,Data_Val!$A$2:$A$3,0)),0,1)) | Q16: =IF(Data!O5="","",IF(ISNUMBER(Data!Q5),IF(AND(Data!Q5>(TODAY()-(Data_Val!$L$3*365.25)),Data!Q5<=(TODAY()-(Data_Val!$L$2*365.25))),0,1),1))
A17: =IF(Data!B9="","",IF(COUNTIFS(Data!A$1:'Data'!A12,Data!A12)<=1,0,1)) -> 0 | C17: =IF(Data!F5="","",(IF(ISNUMBER(MATCH("*@*.?*",Data!F5,0)),0,1)+IF(COUNTIFS(Data!C$1:'Data'!F5,Data!F5)>1,1,0))) -> 1 | D17: =IF(Data!B9="","",IF(ISNUMBER(Data!D7),IF(AND(Data!D7>999999999,Data!D7<=9999999999),IF(COUNTIFS(Data!D$1:'Data'!D7,Data!D7)<=1,0,1),1),1)) -> 0 | E17: =IF(Data!B9="","",IF(ISNUMBER(MATCH(Data!E7,Data_Val!$A$2:$A$3,0)),0,1)) -> 0 | F17: =IF(Data!B9="","",IF(ISNUMBER(Data!#REF!),IF(AND(Data!#REF!>(TODAY()-(Data_Val!$H$3*365.25)),Data!#REF!<=(TODAY()-(Data_Val!$H$2*365.25))),0,1),1)) -> 1 | G17: =IF(Data!B9="","",IF(AND(Data!G7="",Data!H7<>""),1,IF(ISNUMBER(MATCH(Data!G7,Data_Val!$C$2:$C$5,0)),0,1))) -> 0 | H17: =IF(Data!B9="","",IF(AND(Data!G7<>"",Data!H7=""),1,IF(Data!G7="",1,IF(ISNUMBER(MATCH(Data!H7,Data_Val!$D$2:$D$35,0)),0,1)))) -> 1 | I17: =IF(Data!G7="","",IF(Data!G7=Data_Val!$C$2,IF(Data!I7="",0,1),0)) -> 0 | J17: =IF(Data!I7="","",IF(ISNUMBER(MATCH(Data!J7,Data_Val!$A$2:$A$3,0)),0,1)) | K17: =IF(Data!I7="","",IF(ISNUMBER(Data!K7),IF(AND(Data!K7>(TODAY()-(Data_Val!$K$3*365.25)),Data!K7<=(TODAY()-(Data_Val!$K$2*365.25))),0,1),1)) | L17: =IF(Data!G7="","",IF(Data!G7=Data_Val!$C$2,IF(Data!L7="",0,1),0)) -> 0 | M17: =IF(Data!L7="","",IF(ISNUMBER(MATCH(Data!M7,Data_Val!$A$2:$A$3,0)),0,1)) | N17: =IF(Data!L7="","",IF(ISNUMBER(Data!N7),IF(AND(Data!N7>(TODAY()-(Data_Val!$L$3*365.25)),Data!N7<=(TODAY()-(Data_Val!$L$2*365.25))),0,1),1)) | O17: =IF(Data!$G7="","",IF(Data!$G7=Data_Val!$C$2,IF(Data!O7="",0,1),0)) -> 0 | P17: =IF(Data!O7="","",IF(ISNUMBER(MATCH(Data!P7,Data_Val!$A$2:$A$3,0)),0,1)) | Q17: =IF(Data!O7="","",IF(ISNUMBER(Data!Q7),IF(AND(Data!Q7>(TODAY()-(Data_Val!$L$3*365.25)),Data!Q7<=(TODAY()-(Data_Val!$L$2*365.25))),0,1),1))
A18: =IF(Data!B12="","",IF(COUNTIFS(Data!A$1:'Data'!A14,Data!A14)<=1,0,1)) -> 0 | C18: =IF(Data!F7="","",(IF(ISNUMBER(MATCH("*@*.?*",Data!F7,0)),0,1)+IF(COUNTIFS(Data!C$1:'Data'!F7,Data!F7)>1,1,0))) -> 1 | D18: =IF(Data!B12="","",IF(ISNUMBER(Data!#REF!),IF(AND(Data!#REF!>999999999,Data!#REF!<=9999999999),IF(COUNTIFS(Data!D$1:Data!#REF!,Data!#REF!)<=1,0,1),1),1)) -> 1 | E18: =IF(Data!B12="","",IF(ISNUMBER(MATCH(Data!#REF!,Data_Val!$A$2:$A$3,0)),0,1)) -> 1 | F18: =IF(Data!B12="","",IF(ISNUMBER(Data!#REF!),IF(AND(Data!#REF!>(TODAY()-(Data_Val!$H$3*365.25)),Data!#REF!<=(TODAY()-(Data_Val!$H$2*365.25))),0,1),1)) -> 1 | G18: =IF(Data!B12="","",IF(AND(Data!#REF!="",Data!#REF!<>""),1,IF(ISNUMBER(MATCH(Data!#REF!,Data_Val!$C$2:$C$5,0)),0,1))) -> #REF! | H18: =IF(Data!B12="","",IF(AND(Data!#REF!<>"",Data!#REF!=""),1,IF(Data!#REF!="",1,IF(ISNUMBER(MATCH(Data!#REF!,Data_Val!$D$2:$D$35,0)),0,1)))) -> #REF! | I18: =IF(Data!#REF!="","",IF(Data!#REF!=Data_Val!$C$2,IF(Data!#REF!="",0,1),0)) -> #REF! | J18: =IF(Data!#REF!="","",IF(ISNUMBER(MATCH(Data!#REF!,Data_Val!$A$2:$A$3,0)),0,1)) -> #REF! | K18: =IF(Data!#REF!="","",IF(ISNUMBER(Data!#REF!),IF(AND(Data!#REF!>(TODAY()-(Data_Val!$K$3*365.25)),Data!#REF!<=(TODAY()-(Data_Val!$K$2*365.25))),0,1),1)) -> #REF! | L18: =IF(Data!#REF!="","",IF(Data!#REF!=Data_Val!$C$2,IF(Data!#REF!="",0,1),0)) -> #REF! | M18: =IF(Data!#REF!="","",IF(ISNUMBER(MATCH(Data!#REF!,Data_Val!$A$2:$A$3,0)),0,1)) -> #REF! | N18: =IF(Data!#REF!="","",IF(ISNUMBER(Data!#REF!),IF(AND(Data!#REF!>(TODAY()-(Data_Val!$L$3*365.25)),Data!#REF!<=(TODAY()-(Data_Val!$L$2*365.25))),0,1),1)) -> #REF! | O18: =IF(Data!#REF!="","",IF(Data!#REF!=Data_Val!$C$2,IF(Data!#REF!="",0,1),0)) -> #REF! | P18: =IF(Data!#REF!="","",IF(ISNUMBER(MATCH(Data!#REF!,Data_Val!$A$2:$A$3,0)),0,1)) -> #REF! | Q18: =IF(Data!#REF!="","",IF(ISNUMBER(Data!#REF!),IF(AND(Data!#REF!>(TODAY()-(Data_Val!$L$3*365.25)),Data!#REF!<=(TODAY()-(Data_Val!$L$2*365.25))),0,1),1)) -> #REF!
A19: =IF(Data!B15="","",IF(COUNTIFS(Data!A$1:'Data'!A15,Data!A15)<=1,0,1)) | C19: =IF(Data!#REF!="","",(IF(ISNUMBER(MATCH("*@*.?*",Data!#REF!,0)),0,1)+IF(COUNTIFS(Data!C$1:Data!#REF!,Data!#REF!)>1,1,0))) -> #REF! | D19: =IF(Data!B15="","",IF(ISNUMBER(Data!D8),IF(AND(Data!D8>999999999,Data!D8<=9999999999),IF(COUNTIFS(Data!D$1:'Data'!D8,Data!D8)<=1,0,1),1),1)) | E19: =IF(Data!B15="","",IF(ISNUMBER(MATCH(Data!E8,Data_Val!$A$2:$A$3,0)),0,1)) | F19: =IF(Data!B15="","",IF(ISNUMBER(Data!#REF!),IF(AND(Data!#REF!>(TODAY()-(Data_Val!$H$3*365.25)),Data!#REF!<=(TODAY()-(Data_Val!$H$2*365.25))),0,1),1)) | G19: =IF(Data!B15="","",IF(AND(Data!G8="",Data!H8<>""),1,IF(ISNUMBER(MATCH(Data!G8,Data_Val!$C$2:$C$5,0)),0,1))) | H19: =IF(Data!B15="","",IF(AND(Data!G8<>"",Data!H8=""),1,IF(Data!G8="",1,IF(ISNUMBER(MATCH(Data!H8,Data_Val!$D$2:$D$35,0)),0,1)))) | I19: =IF(Data!G8="","",IF(Data!G8=Data_Val!$C$2,IF(Data!I8="",0,1),0)) -> 0 | J19: =IF(Data!I8="","",IF(ISNUMBER(MATCH(Data!J8,Data_Val!$A$2:$A$3,0)),0,1)) | K19: =IF(Data!I8="","",IF(ISNUMBER(Data!K8),IF(AND(Data!K8>(TODAY()-(Data_Val!$K$3*365.25)),Data!K8<=(TODAY()-(Data_Val!$K$2*365.25))),0,1),1)) | L19: =IF(Data!G8="","",IF(Data!G8=Data_Val!$C$2,IF(Data!L8="",0,1),0)) -> 0 | M19: =IF(Data!L8="","",IF(ISNUMBER(MATCH(Data!M8,Data_Val!$A$2:$A$3,0)),0,1)) | N19: =IF(Data!L8="","",IF(ISNUMBER(Data!N8),IF(AND(Data!N8>(TODAY()-(Data_Val!$L$3*365.25)),Data!N8<=(TODAY()-(Data_Val!$L$2*365.25))),0,1),1)) | O19: =IF(Data!$G8="","",IF(Data!$G8=Data_Val!$C$2,IF(Data!O8="",0,1),0)) -> 0 | P19: =IF(Data!O8="","",IF(ISNUMBER(MATCH(Data!P8,Data_Val!$A$2:$A$3,0)),0,1)) | Q19: =IF(Data!O8="","",IF(ISNUMBER(Data!Q8),IF(AND(Data!Q8>(TODAY()-(Data_Val!$L$3*365.25)),Data!Q8<=(TODAY()-(Data_Val!$L$2*365.25))),0,1),1))
A20: =IF(#REF!="","",IF(COUNTIFS(Data!A$1:#REF!,#REF!)<=1,0,1)) -> #REF! | C20: =IF(Data!#REF!="","",(IF(ISNUMBER(MATCH("*@*.?*",Data!#REF!,0)),0,1)+IF(COUNTIFS(Data!C$1:Data!#REF!,Data!#REF!)>1,1,0))) -> #REF! | D20: =IF(#REF!="","",IF(ISNUMBER(Data!D10),IF(AND(Data!D10>999999999,Data!D10<=9999999999),IF(COUNTIFS(Data!D$1:'Data'!D10,Data!D10)<=1,0,1),1),1)) -> #REF! | E20: =IF(#REF!="","",IF(ISNUMBER(MATCH(Data!E10,Data_Val!$A$2:$A$3,0)),0,1)) -> #REF! | F20: =IF(#REF!="","",IF(ISNUMBER(Data!#REF!),IF(AND(Data!#REF!>(TODAY()-(Data_Val!$H$3*365.25)),Data!#REF!<=(TODAY()-(Data_Val!$H$2*365.25))),0,1),1)) -> #REF! | G20: =IF(#REF!="","",IF(AND(Data!G10="",Data!H10<>""),1,IF(ISNUMBER(MATCH(Data!G10,Data_Val!$C$2:$C$5,0)),0,1))) -> #REF! | H20: =IF(#REF!="","",IF(AND(Data!G10<>"",Data!H10=""),1,IF(Data!G10="",1,IF(ISNUMBER(MATCH(Data!H10,Data_Val!$D$2:$D$35,0)),0,1)))) -> #REF! | I20: =IF(Data!G10="","",IF(Data!G10=Data_Val!$C$2,IF(Data!I10="",0,1),0)) -> 0 | J20: =IF(Data!I10="","",IF(ISNUMBER(MATCH(Data!J10,Data_Val!$A$2:$A$3,0)),0,1)) | K20: =IF(Data!I10="","",IF(ISNUMBER(Data!K10),IF(AND(Data!K10>(TODAY()-(Data_Val!$K$3*365.25)),Data!K10<=(TODAY()-(Data_Val!$K$2*365.25))),0,1),1)) | L20: =IF(Data!G10="","",IF(Data!G10=Data_Val!$C$2,IF(Data!L10="",0,1),0)) -> 0 | M20: =IF(Data!L10="","",IF(ISNUMBER(MATCH(Data!M10,Data_Val!$A$2:$A$3,0)),0,1)) | N20: =IF(Data!L10="","",IF(ISNUMBER(Data!N10),IF(AND(Data!N10>(TODAY()-(Data_Val!$L$3*365.25)),Data!N10<=(TODAY()-(Data_Val!$L$2*365.25))),0,1),1)) | O20: =IF(Data!$G10="","",IF(Data!$G10=Data_Val!$C$2,IF(Data!O10="",0,1),0)) -> 0 | P20: =IF(Data!O10="","",IF(ISNUMBER(MATCH(Data!P10,Data_Val!$A$2:$A$3,0)),0,1)) | Q20: =IF(Data!O10="","",IF(ISNUMBER(Data!Q10),IF(AND(Data!Q10>(TODAY()-(Data_Val!$L$3*365.25)),Data!Q10<=(TODAY()-(Data_Val!$L$2*365.25))),0,1),1))
A21: =IF(#REF!="","",IF(COUNTIFS(Data!A$1:#REF!,#REF!)<=1,0,1)) -> #REF! | C21: =IF(Data!F9="","",(IF(ISNUMBER(MATCH("*@*.?*",Data!F9,0)),0,1)+IF(COUNTIFS(Data!C$1:'Data'!F9,Data!F9)>1,1,0))) -> 1 | D21: =IF(#REF!="","",IF(ISNUMBER(Data!D11),IF(AND(Data!D11>999999999,Data!D11<=9999999999),IF(COUNTIFS(Data!D$1:'Data'!D11,Data!D11)<=1,0,1),1),1)) -> #REF! | E21: =IF(#REF!="","",IF(ISNUMBER(MATCH(Data!E11,Data_Val!$A$2:$A$3,0)),0,1)) -> #REF! | F21: =IF(#REF!="","",IF(ISNUMBER(Data!#REF!),IF(AND(Data!#REF!>(TODAY()-(Data_Val!$H$3*365.25)),Data!#REF!<=(TODAY()-(Data_Val!$H$2*365.25))),0,1),1)) -> #REF! | G21: =IF(#REF!="","",IF(AND(Data!G11="",Data!H11<>""),1,IF(ISNUMBER(MATCH(Data!G11,Data_Val!$C$2:$C$5,0)),0,1))) -> #REF! | H21: =IF(#REF!="","",IF(AND(Data!G11<>"",Data!H11=""),1,IF(Data!G11="",1,IF(ISNUMBER(MATCH(Data!H11,Data_Val!$D$2:$D$35,0)),0,1)))) -> #REF! | I21: =IF(Data!G11="","",IF(Data!G11=Data_Val!$C$2,IF(Data!I11="",0,1),0)) -> 0 | J21: =IF(Data!I11="","",IF(ISNUMBER(MATCH(Data!J11,Data_Val!$A$2:$A$3,0)),0,1)) | K21: =IF(Data!I11="","",IF(ISNUMBER(Data!K11),IF(AND(Data!K11>(TODAY()-(Data_Val!$K$3*365.25)),Data!K11<=(TODAY()-(Data_Val!$K$2*365.25))),0,1),1)) | L21: =IF(Data!G11="","",IF(Data!G11=Data_Val!$C$2,IF(Data!L11="",0,1),0)) -> 0 | M21: =IF(Data!L11="","",IF(ISNUMBER(MATCH(Data!M11,Data_Val!$A$2:$A$3,0)),0,1)) | N21: =IF(Data!L11="","",IF(ISNUMBER(Data!N11),IF(AND(Data!N11>(TODAY()-(Data_Val!$L$3*365.25)),Data!N11<=(TODAY()-(Data_Val!$L$2*365.25))),0,1),1)) | O21: =IF(Data!$G11="","",IF(Data!$G11=Data_Val!$C$2,IF(Data!O11="",0,1),0)) -> 0 | P21: =IF(Data!O11="","",IF(ISNUMBER(MATCH(Data!P11,Data_Val!$A$2:$A$3,0)),0,1)) | Q21: =IF(Data!O11="","",IF(ISNUMBER(Data!Q11),IF(AND(Data!Q11>(TODAY()-(Data_Val!$L$3*365.25)),Data!Q11<=(TODAY()-(Data_Val!$L$2*365.25))),0,1),1))
A22: =IF(Data!B16="","",IF(COUNTIFS(Data!A$1:'Data'!A16,Data!A16)<=1,0,1)) | C22: =IF(Data!F12="","",(IF(ISNUMBER(MATCH("*@*.?*",Data!F12,0)),0,1)+IF(COUNTIFS(Data!C$1:'Data'!F12,Data!F12)>1,1,0))) -> 1 | D22: =IF(Data!B16="","",IF(ISNUMBER(Data!D14),IF(AND(Data!D14>999999999,Data!D14<=9999999999),IF(COUNTIFS(Data!D$1:'Data'!D14,Data!D14)<=1,0,1),1),1)) | E22: =IF(Data!B16="","",IF(ISNUMBER(MATCH(Data!E14,Data_Val!$A$2:$A$3,0)),0,1)) | F22: =IF(Data!B16="","",IF(ISNUMBER(Data!F14),IF(AND(Data!F14>(TODAY()-(Data_Val!$H$3*365.25)),Data!F14<=(TODAY()-(Data_Val!$H$2*365.25))),0,1),1)) | G22: =IF(Data!B16="","",IF(AND(Data!G14="",Data!H14<>""),1,IF(ISNUMBER(MATCH(Data!G14,Data_Val!$C$2:$C$5,0)),0,1))) | H22: =IF(Data!B16="","",IF(AND(Data!G14<>"",Data!H14=""),1,IF(Data!G14="",1,IF(ISNUMBER(MATCH(Data!H14,Data_Val!$D$2:$D$35,0)),0,1)))) | I22: =IF(Data!G14="","",IF(Data!G14=Data_Val!$C$2,IF(Data!I14="",0,1),0)) | J22: =IF(Data!I14="","",IF(ISNUMBER(MATCH(Data!J14,Data_Val!$A$2:$A$3,0)),0,1)) | K22: =IF(Data!I14="","",IF(ISNUMBER(Data!K14),IF(AND(Data!K14>(TODAY()-(Data_Val!$K$3*365.25)),Data!K14<=(TODAY()-(Data_Val!$K$2*365.25))),0,1),1)) | L22: =IF(Data!G14="","",IF(Data!G14=Data_Val!$C$2,IF(Data!L14="",0,1),0)) | M22: =IF(Data!L14="","",IF(ISNUMBER(MATCH(Data!M14,Data_Val!$A$2:$A$3,0)),0,1)) | N22: =IF(Data!L14="","",IF(ISNUMBER(Data!N14),IF(AND(Data!N14>(TODAY()-(Data_Val!$L$3*365.25)),Data!N14<=(TODAY()-(Data_Val!$L$2*365.25))),0,1),1)) | O22: =IF(Data!$G14="","",IF(Data!$G14=Data_Val!$C$2,IF(Data!O14="",0,1),0)) | P22: =IF(Data!O14="","",IF(ISNUMBER(MATCH(Data!P14,Data_Val!$A$2:$A$3,0)),0,1)) | Q22: =IF(Data!O14="","",IF(ISNUMBER(Data!Q14),IF(AND(Data!Q14>(TODAY()-(Data_Val!$L$3*365.25)),Data!Q14<=(TODAY()-(Data_Val!$L$2*365.25))),0,1),1))
A23: =IF(Data!#REF!="","",IF(COUNTIFS(Data!A$1:'Data'!A17,Data!A17)<=1,0,1)) -> #REF! | C23: =IF(Data!C15="","",(IF(ISNUMBER(MATCH("*@*.?*",Data!C15,0)),0,1)+IF(COUNTIFS(Data!C$1:'Data'!C15,Data!C15)>1,1,0))) | D23: =IF(Data!#REF!="","",IF(ISNUMBER(Data!D15),IF(AND(Data!D15>999999999,Data!D15<=9999999999),IF(COUNTIFS(Data!D$1:'Data'!D15,Data!D15)<=1,0,1),1),1)) -> #REF! | E23: =IF(Data!#REF!="","",IF(ISNUMBER(MATCH(Data!E15,Data_Val!$A$2:$A$3,0)),0,1)) -> #REF! | F23: =IF(Data!#REF!="","",IF(ISNUMBER(Data!F15),IF(AND(Data!F15>(TODAY()-(Data_Val!$H$3*365.25)),Data!F15<=(TODAY()-(Data_Val!$H$2*365.25))),0,1),1)) -> #REF! | G23: =IF(Data!#REF!="","",IF(AND(Data!G15="",Data!H15<>""),1,IF(ISNUMBER(MATCH(Data!G15,Data_Val!$C$2:$C$5,0)),0,1))) -> #REF! | H23: =IF(Data!#REF!="","",IF(AND(Data!G15<>"",Data!H15=""),1,IF(Data!G15="",1,IF(ISNUMBER(MATCH(Data!H15,Data_Val!$D$2:$D$35,0)),0,1)))) -> #REF! | I23: =IF(Data!G15="","",IF(Data!G15=Data_Val!$C$2,IF(Data!I15="",0,1),0)) | J23: =IF(Data!I15="","",IF(ISNUMBER(MATCH(Data!J15,Data_Val!$A$2:$A$3,0)),0,1)) | K23: =IF(Data!I15="","",IF(ISNUMBER(Data!K15),IF(AND(Data!K15>(TODAY()-(Data_Val!$K$3*365.25)),Data!K15<=(TODAY()-(Data_Val!$K$2*365.25))),0,1),1)) | L23: =IF(Data!G15="","",IF(Data!G15=Data_Val!$C$2,IF(Data!L15="",0,1),0)) | M23: =IF(Data!L15="","",IF(ISNUMBER(MATCH(Data!M15,Data_Val!$A$2:$A$3,0)),0,1)) | N23: =IF(Data!L15="","",IF(ISNUMBER(Data!N15),IF(AND(Data!N15>(TODAY()-(Data_Val!$L$3*365.25)),Data!N15<=(TODAY()-(Data_Val!$L$2*365.25))),0,1),1)) | O23: =IF(Data!$G15="","",IF(Data!$G15=Data_Val!$C$2,IF(Data!O15="",0,1),0)) | P23: =IF(Data!O15="","",IF(ISNUMBER(MATCH(Data!P15,Data_Val!$A$2:$A$3,0)),0,1)) | Q23: =IF(Data!O15="","",IF(ISNUMBER(Data!Q15),IF(AND(Data!Q15>(TODAY()-(Data_Val!$L$3*365.25)),Data!Q15<=(TODAY()-(Data_Val!$L$2*365.25))),0,1),1))
A24: =IF(Data!B18="","",IF(COUNTIFS(Data!A$1:'Data'!A18,Data!A18)<=1,0,1)) | C24: =IF(#REF!="","",(IF(ISNUMBER(MATCH("*@*.?*",#REF!,0)),0,1)+IF(COUNTIFS(Data!C$1:#REF!,#REF!)>1,1,0))) -> #REF! | D24: =IF(Data!B18="","",IF(ISNUMBER(#REF!),IF(AND(#REF!>999999999,#REF!<=9999999999),IF(COUNTIFS(Data!D$1:#REF!,#REF!)<=1,0,1),1),1)) | E24: =IF(Data!B18="","",IF(ISNUMBER(MATCH(#REF!,Data_Val!$A$2:$A$3,0)),0,1)) | F24: =IF(Data!B18="","",IF(ISNUMBER(#REF!),IF(AND(#REF!>(TODAY()-(Data_Val!$H$3*365.25)),#REF!<=(TODAY()-(Data_Val!$H$2*365.25))),0,1),1)) | G24: =IF(Data!B18="","",IF(AND(#REF!="",#REF!<>""),1,IF(ISNUMBER(MATCH(#REF!,Data_Val!$C$2:$C$5,0)),0,1))) | H24: =IF(Data!B18="","",IF(AND(#REF!<>"",#REF!=""),1,IF(#REF!="",1,IF(ISNUMBER(MATCH(#REF!,Data_Val!$D$2:$D$35,0)),0,1)))) | I24: =IF(#REF!="","",IF(#REF!=Data_Val!$C$2,IF(#REF!="",0,1),0)) -> #REF! | J24: =IF(#REF!="","",IF(ISNUMBER(MATCH(#REF!,Data_Val!$A$2:$A$3,0)),0,1)) -> #REF! | K24: =IF(#REF!="","",IF(ISNUMBER(#REF!),IF(AND(#REF!>(TODAY()-(Data_Val!$K$3*365.25)),#REF!<=(TODAY()-(Data_Val!$K$2*365.25))),0,1),1)) -> #REF! | L24: =IF(#REF!="","",IF(#REF!=Data_Val!$C$2,IF(#REF!="",0,1),0)) -> #REF! | M24: =IF(#REF!="","",IF(ISNUMBER(MATCH(#REF!,Data_Val!$A$2:$A$3,0)),0,1)) -> #REF! | N24: =IF(#REF!="","",IF(ISNUMBER(#REF!),IF(AND(#REF!>(TODAY()-(Data_Val!$L$3*365.25)),#REF!<=(TODAY()-(Data_Val!$L$2*365.25))),0,1),1)) -> #REF! | O24: =IF(#REF!="","",IF(#REF!=Data_Val!$C$2,IF(#REF!="",0,1),0)) -> #REF! | P24: =IF(#REF!="","",IF(ISNUMBER(MATCH(#REF!,Data_Val!$A$2:$A$3,0)),0,1)) -> #REF! | Q24: =IF(#REF!="","",IF(ISNUMBER(#REF!),IF(AND(#REF!>(TODAY()-(Data_Val!$L$3*365.25)),#REF!<=(TODAY()-(Data_Val!$L$2*365.25))),0,1),1)) -> #REF!
A25: =IF(Data!B19="","",IF(COUNTIFS(Data!A$1:'Data'!A19,Data!A19)<=1,0,1)) | C25: =IF(#REF!="","",(IF(ISNUMBER(MATCH("*@*.?*",#REF!,0)),0,1)+IF(COUNTIFS(Data!C$1:#REF!,#REF!)>1,1,0))) -> #REF! | D25: =IF(Data!B19="","",IF(ISNUMBER(#REF!),IF(AND(#REF!>999999999,#REF!<=9999999999),IF(COUNTIFS(Data!D$1:#REF!,#REF!)<=1,0,1),1),1)) | E25: =IF(Data!B19="","",IF(ISNUMBER(MATCH(#REF!,Data_Val!$A$2:$A$3,0)),0,1)) | F25: =IF(Data!B19="","",IF(ISNUMBER(#REF!),IF(AND(#REF!>(TODAY()-(Data_Val!$H$3*365.25)),#REF!<=(TODAY()-(Data_Val!$H$2*365.25))),0,1),1)) | G25: =IF(Data!B19="","",IF(AND(#REF!="",#REF!<>""),1,IF(ISNUMBER(MATCH(#REF!,Data_Val!$C$2:$C$5,0)),0,1))) | H25: =IF(Data!B19="","",IF(AND(#REF!<>"",#REF!=""),1,IF(#REF!="",1,IF(ISNUMBER(MATCH(#REF!,Data_Val!$D$2:$D$35,0)),0,1)))) | I25: =IF(#REF!="","",IF(#REF!=Data_Val!$C$2,IF(#REF!="",0,1),0)) -> #REF! | J25: =IF(#REF!="","",IF(ISNUMBER(MATCH(#REF!,Data_Val!$A$2:$A$3,0)),0,1)) -> #REF! | K25: =IF(#REF!="","",IF(ISNUMBER(#REF!),IF(AND(#REF!>(TODAY()-(Data_Val!$K$3*365.25)),#REF!<=(TODAY()-(Data_Val!$K$2*365.25))),0,1),1)) -> #REF! | L25: =IF(#REF!="","",IF(#REF!=Data_Val!$C$2,IF(#REF!="",0,1),0)) -> #REF! | M25: =IF(#REF!="","",IF(ISNUMBER(MATCH(#REF!,Data_Val!$A$2:$A$3,0)),0,1)) -> #REF! | N25: =IF(#REF!="","",IF(ISNUMBER(#REF!),IF(AND(#REF!>(TODAY()-(Data_Val!$L$3*365.25)),#REF!<=(TODAY()-(Data_Val!$L$2*365.25))),0,1),1)) -> #REF! | O25: =IF(#REF!="","",IF(#REF!=Data_Val!$C$2,IF(#REF!="",0,1),0)) -> #REF! | P25: =IF(#REF!="","",IF(ISNUMBER(MATCH(#REF!,Data_Val!$A$2:$A$3,0)),0,1)) -> #REF! | Q25: =IF(#REF!="","",IF(ISNUMBER(#REF!),IF(AND(#REF!>(TODAY()-(Data_Val!$L$3*365.25)),#REF!<=(TODAY()-(Data_Val!$L$2*365.25))),0,1),1)) -> #REF!
A26: =IF(Data!B20="","",IF(COUNTIFS(Data!A$1:'Data'!A20,Data!A20)<=1,0,1)) | C26: =IF(Data!C16="","",(IF(ISNUMBER(MATCH("*@*.?*",Data!C16,0)),0,1)+IF(COUNTIFS(Data!C$1:'Data'!C16,Data!C16)>1,1,0))) | D26: =IF(Data!B20="","",IF(ISNUMBER(Data!D16),IF(AND(Data!D16>999999999,Data!D16<=9999999999),IF(COUNTIFS(Data!D$1:'Data'!D16,Data!D16)<=1,0,1),1),1)) | E26: =IF(Data!B20="","",IF(ISNUMBER(MATCH(Data!E16,Data_Val!$A$2:$A$3,0)),0,1)) | F26: =IF(Data!B20="","",IF(ISNUMBER(Data!F16),IF(AND(Data!F16>(TODAY()-(Data_Val!$H$3*365.25)),Data!F16<=(TODAY()-(Data_Val!$H$2*365.25))),0,1),1)) | G26: =IF(Data!B20="","",IF(AND(Data!G16="",Data!H16<>""),1,IF(ISNUMBER(MATCH(Data!G16,Data_Val!$C$2:$C$5,0)),0,1))) | H26: =IF(Data!B20="","",IF(AND(Data!G16<>"",Data!H16=""),1,IF(Data!G16="",1,IF(ISNUMBER(MATCH(Data!H16,Data_Val!$D$2:$D$35,0)),0,1)))) | I26: =IF(Data!G16="","",IF(Data!G16=Data_Val!$C$2,IF(Data!I16="",0,1),0)) | J26: =IF(Data!I16="","",IF(ISNUMBER(MATCH(Data!J16,Data_Val!$A$2:$A$3,0)),0,1)) | K26: =IF(Data!I16="","",IF(ISNUMBER(Data!K16),IF(AND(Data!K16>(TODAY()-(Data_Val!$K$3*365.25)),Data!K16<=(TODAY()-(Data_Val!$K$2*365.25))),0,1),1)) | L26: =IF(Data!G16="","",IF(Data!G16=Data_Val!$C$2,IF(Data!L16="",0,1),0)) | M26: =IF(Data!L16="","",IF(ISNUMBER(MATCH(Data!M16,Data_Val!$A$2:$A$3,0)),0,1)) | N26: =IF(Data!L16="","",IF(ISNUMBER(Data!N16),IF(AND(Data!N16>(TODAY()-(Data_Val!$L$3*365.25)),Data!N16<=(TODAY()-(Data_Val!$L$2*365.25))),0,1),1)) | O26: =IF(Data!$G16="","",IF(Data!$G16=Data_Val!$C$2,IF(Data!O16="",0,1),0)) | P26: =IF(Data!O16="","",IF(ISNUMBER(MATCH(Data!P16,Data_Val!$A$2:$A$3,0)),0,1)) | Q26: =IF(Data!O16="","",IF(ISNUMBER(Data!Q16),IF(AND(Data!Q16>(TODAY()-(Data_Val!$L$3*365.25)),Data!Q16<=(TODAY()-(Data_Val!$L$2*365.25))),0,1),1))
A27: =IF(Data!B21="","",IF(COUNTIFS(Data!A$1:'Data'!A21,Data!A21)<=1,0,1)) | C27: =IF(Data!C17="","",(IF(ISNUMBER(MATCH("*@*.?*",Data!C17,0)),0,1)+IF(COUNTIFS(Data!C$1:'Data'!C17,Data!C17)>1,1,0))) | D27: =IF(Data!B21="","",IF(ISNUMBER(Data!D17),IF(AND(Data!D17>999999999,Data!D17<=9999999999),IF(COUNTIFS(Data!D$1:'Data'!D17,Data!D17)<=1,0,1),1),1)) | E27: =IF(Data!B21="","",IF(ISNUMBER(MATCH(Data!E17,Data_Val!$A$2:$A$3,0)),0,1)) | F27: =IF(Data!B21="","",IF(ISNUMBER(Data!F17),IF(AND(Data!F17>(TODAY()-(Data_Val!$H$3*365.25)),Data!F17<=(TODAY()-(Data_Val!$H$2*365.25))),0,1),1)) | G27: =IF(Data!B21="","",IF(AND(Data!G17="",Data!H17<>""),1,IF(ISNUMBER(MATCH(Data!G17,Data_Val!$C$2:$C$5,0)),0,1))) | H27: =IF(Data!B21="","",IF(AND(Data!G17<>"",Data!H17=""),1,IF(Data!G17="",1,IF(ISNUMBER(MATCH(Data!H17,Data_Val!$D$2:$D$35,0)),0,1)))) | I27: =IF(Data!G17="","",IF(Data!G17=Data_Val!$C$2,IF(Data!I17="",0,1),0)) | J27: =IF(Data!I17="","",IF(ISNUMBER(MATCH(Data!J17,Data_Val!$A$2:$A$3,0)),0,1)) | K27: =IF(Data!I17="","",IF(ISNUMBER(Data!K17),IF(AND(Data!K17>(TODAY()-(Data_Val!$K$3*365.25)),Data!K17<=(TODAY()-(Data_Val!$K$2*365.25))),0,1),1)) | L27: =IF(Data!G17="","",IF(Data!G17=Data_Val!$C$2,IF(Data!L17="",0,1),0)) | M27: =IF(Data!L17="","",IF(ISNUMBER(MATCH(Data!M17,Data_Val!$A$2:$A$3,0)),0,1)) | N27: =IF(Data!L17="","",IF(ISNUMBER(Data!N17),IF(AND(Data!N17>(TODAY()-(Data_Val!$L$3*365.25)),Data!N17<=(TODAY()-(Data_Val!$L$2*365.25))),0,1),1)) | O27: =IF(Data!$G17="","",IF(Data!$G17=Data_Val!$C$2,IF(Data!O17="",0,1),0)) | P27: =IF(Data!O17="","",IF(ISNUMBER(MATCH(Data!P17,Data_Val!$A$2:$A$3,0)),0,1)) | Q27: =IF(Data!O17="","",IF(ISNUMBER(Data!Q17),IF(AND(Data!Q17>(TODAY()-(Data_Val!$L$3*365.25)),Data!Q17<=(TODAY()-(Data_Val!$L$2*365.25))),0,1),1))
A28: =IF(#REF!="","",IF(COUNTIFS(Data!A$1:#REF!,#REF!)<=1,0,1)) -> #REF! | C28: =IF(Data!C18="","",(IF(ISNUMBER(MATCH("*@*.?*",Data!C18,0)),0,1)+IF(COUNTIFS(Data!C$1:'Data'!C18,Data!C18)>1,1,0))) | D28: =IF(#REF!="","",IF(ISNUMBER(Data!D18),IF(AND(Data!D18>999999999,Data!D18<=9999999999),IF(COUNTIFS(Data!D$1:'Data'!D18,Data!D18)<=1,0,1),1),1)) -> #REF! | E28: =IF(#REF!="","",IF(ISNUMBER(MATCH(Data!E18,Data_Val!$A$2:$A$3,0)),0,1)) -> #REF! | F28: =IF(#REF!="","",IF(ISNUMBER(Data!F18),IF(AND(Data!F18>(TODAY()-(Data_Val!$H$3*365.25)),Data!F18<=(TODAY()-(Data_Val!$H$2*365.25))),0,1),1)) -> #REF! | G28: =IF(#REF!="","",IF(AND(Data!G18="",Data!H18<>""),1,IF(ISNUMBER(MATCH(Data!G18,Data_Val!$C$2:$C$5,0)),0,1))) -> #REF! | H28: =IF(#REF!="","",IF(AND(Data!G18<>"",Data!H18=""),1,IF(Data!G18="",1,IF(ISNUMBER(MATCH(Data!H18,Data_Val!$D$2:$D$35,0)),0,1)))) -> #REF! | I28: =IF(Data!G18="","",IF(Data!G18=Data_Val!$C$2,IF(Data!I18="",0,1),0)) | J28: =IF(Data!I18="","",IF(ISNUMBER(MATCH(Data!J18,Data_Val!$A$2:$A$3,0)),0,1)) | K28: =IF(Data!I18="","",IF(ISNUMBER(Data!K18),IF(AND(Data!K18>(TODAY()-(Data_Val!$K$3*365.25)),Data!K18<=(TODAY()-(Data_Val!$K$2*365.25))),0,1),1)) | L28: =IF(Data!G18="","",IF(Data!G18=Data_Val!$C$2,IF(Data!L18="",0,1),0)) | M28: =IF(Data!L18="","",IF(ISNUMBER(MATCH(Data!M18,Data_Val!$A$2:$A$3,0)),0,1)) | N28: =IF(Data!L18="","",IF(ISNUMBER(Data!N18),IF(AND(Data!N18>(TODAY()-(Data_Val!$L$3*365.25)),Data!N18<=(TODAY()-(Data_Val!$L$2*365.25))),0,1),1)) | O28: =IF(Data!$G18="","",IF(Data!$G18=Data_Val!$C$2,IF(Data!O18="",0,1),0)) | P28: =IF(Data!O18="","",IF(ISNUMBER(MATCH(Data!P18,Data_Val!$A$2:$A$3,0)),0,1)) | Q28: =IF(Data!O18="","",IF(ISNUMBER(Data!Q18),IF(AND(Data!Q18>(TODAY()-(Data_Val!$L$3*365.25)),Data!Q18<=(TODAY()-(Data_Val!$L$2*365.25))),0,1),1))
A29: =IF(#REF!="","",IF(COUNTIFS(Data!A$1:#REF!,#REF!)<=1,0,1)) -> #REF! | C29: =IF(Data!C19="","",(IF(ISNUMBER(MATCH("*@*.?*",Data!C19,0)),0,1)+IF(COUNTIFS(Data!C$1:'Data'!C19,Data!C19)>1,1,0))) | D29: =IF(#REF!="","",IF(ISNUMBER(Data!D19),IF(AND(Data!D19>999999999,Data!D19<=9999999999),IF(COUNTIFS(Data!D$1:'Data'!D19,Data!D19)<=1,0,1),1),1)) -> #REF! | E29: =IF(#REF!="","",IF(ISNUMBER(MATCH(Data!E19,Data_Val!$A$2:$A$3,0)),0,1)) -> #REF! | F29: =IF(#REF!="","",IF(ISNUMBER(Data!F19),IF(AND(Data!F19>(TODAY()-(Data_Val!$H$3*365.25)),Data!F19<=(TODAY()-(Data_Val!$H$2*365.25))),0,1),1)) -> #REF! | G29: =IF(#REF!="","",IF(AND(Data!G19="",Data!H19<>""),1,IF(ISNUMBER(MATCH(Data!G19,Data_Val!$C$2:$C$5,0)),0,1))) -> #REF! | H29: =IF(#REF!="","",IF(AND(Data!G19<>"",Data!H19=""),1,IF(Data!G19="",1,IF(ISNUMBER(MATCH(Data!H19,Data_Val!$D$2:$D$35,0)),0,1)))) -> #REF! | I29: =IF(Data!G19="","",IF(Data!G19=Data_Val!$C$2,IF(Data!I19="",0,1),0)) | J29: =IF(Data!I19="","",IF(ISNUMBER(MATCH(Data!J19,Data_Val!$A$2:$A$3,0)),0,1)) | K29: =IF(Data!I19="","",IF(ISNUMBER(Data!K19),IF(AND(Data!K19>(TODAY()-(Data_Val!$K$3*365.25)),Data!K19<=(TODAY()-(Data_Val!$K$2*365.25))),0,1),1)) | L29: =IF(Data!G19="","",IF(Data!G19=Data_Val!$C$2,IF(Data!L19="",0,1),0)) | M29: =IF(Data!L19="","",IF(ISNUMBER(MATCH(Data!M19,Data_Val!$A$2:$A$3,0)),0,1)) | N29: =IF(Data!L19="","",IF(ISNUMBER(Data!N19),IF(AND(Data!N19>(TODAY()-(Data_Val!$L$3*365.25)),Data!N19<=(TODAY()-(Data_Val!$L$2*365.25))),0,1),1)) | O29: =IF(Data!$G19="","",IF(Data!$G19=Data_Val!$C$2,IF(Data!O19="",0,1),0)) | P29: =IF(Data!O19="","",IF(ISNUMBER(MATCH(Data!P19,Data_Val!$A$2:$A$3,0)),0,1)) | Q29: =IF(Data!O19="","",IF(ISNUMBER(Data!Q19),IF(AND(Data!Q19>(TODAY()-(Data_Val!$L$3*365.25)),Data!Q19<=(TODAY()-(Data_Val!$L$2*365.25))),0,1),1))
A30: =IF(#REF!="","",IF(COUNTIFS(Data!A$1:#REF!,#REF!)<=1,0,1)) -> #REF! | C30: =IF(Data!C20="","",(IF(ISNUMBER(MATCH("*@*.?*",Data!C20,0)),0,1)+IF(COUNTIFS(Data!C$1:'Data'!C20,Data!C20)>1,1,0))) | D30: =IF(#REF!="","",IF(ISNUMBER(Data!D20),IF(AND(Data!D20>999999999,Data!D20<=9999999999),IF(COUNTIFS(Data!D$1:'Data'!D20,Data!D20)<=1,0,1),1),1)) -> #REF! | E30: =IF(#REF!="","",IF(ISNUMBER(MATCH(Data!E20,Data_Val!$A$2:$A$3,0)),0,1)) -> #REF! | F30: =IF(#REF!="","",IF(ISNUMBER(Data!F20),IF(AND(Data!F20>(TODAY()-(Data_Val!$H$3*365.25)),Data!F20<=(TODAY()-(Data_Val!$H$2*365.25))),0,1),1)) -> #REF! | G30: =IF(#REF!="","",IF(AND(Data!G20="",Data!H20<>""),1,IF(ISNUMBER(MATCH(Data!G20,Data_Val!$C$2:$C$5,0)),0,1))) -> #REF! | H30: =IF(#REF!="","",IF(AND(Data!G20<>"",Data!H20=""),1,IF(Data!G20="",1,IF(ISNUMBER(MATCH(Data!H20,Data_Val!$D$2:$D$35,0)),0,1)))) -> #REF! | I30: =IF(Data!G20="","",IF(Data!G20=Data_Val!$C$2,IF(Data!I20="",0,1),0)) | J30: =IF(Data!I20="","",IF(ISNUMBER(MATCH(Data!J20,Data_Val!$A$2:$A$3,0)),0,1)) | K30: =IF(Data!I20="","",IF(ISNUMBER(Data!K20),IF(AND(Data!K20>(TODAY()-(Data_Val!$K$3*365.25)),Data!K20<=(TODAY()-(Data_Val!$K$2*365.25))),0,1),1)) | L30: =IF(Data!G20="","",IF(Data!G20=Data_Val!$C$2,IF(Data!L20="",0,1),0)) | M30: =IF(Data!L20="","",IF(ISNUMBER(MATCH(Data!M20,Data_Val!$A$2:$A$3,0)),0,1)) | N30: =IF(Data!L20="","",IF(ISNUMBER(Data!N20),IF(AND(Data!N20>(TODAY()-(Data_Val!$L$3*365.25)),Data!N20<=(TODAY()-(Data_Val!$L$2*365.25))),0,1),1)) | O30: =IF(Data!$G20="","",IF(Data!$G20=Data_Val!$C$2,IF(Data!O20="",0,1),0)) | P30: =IF(Data!O20="","",IF(ISNUMBER(MATCH(Data!P20,Data_Val!$A$2:$A$3,0)),0,1)) | Q30: =IF(Data!O20="","",IF(ISNUMBER(Data!Q20),IF(AND(Data!Q20>(TODAY()-(Data_Val!$L$3*365.25)),Data!Q20<=(TODAY()-(Data_Val!$L$2*365.25))),0,1),1))
